Workbook

Sheet Setup Guide
B1: SHEETS & CELLS — SALES DASHBOARD 2026
B2: Free sales dashboard with pipeline funnel + rep leaderboard + quota tracking. sheetsandcells.com/templates/sales-dashboard/
B4: ▶ QUICK START (5 minutes)
A6: 1. | B6: Open QUOTAS. Update each rep's name, email, territory, and monthly quota. Add or remove rows for your team.
A8: 2. | B8: Open DEAL PIPELINE. The pre-filled sample deals show how the template works. Replace with your real deals: deal name, client, rep (dropdown), stage (dropdown), value, expected close date.
A10: 3. | B10: Open DASHBOARD. Four KPI cards at top, pipeline funnel in middle, rep leaderboard at bottom — all auto-calculated. Change any deal stage on the Deal Pipeline sheet to see everything update.
A12: 4. | B12: Open REP PERFORMANCE for per-rep detail. Open HISTORICAL TRENDS for 12-month team view. Both feed off the Deal Pipeline sheet.
B15: ▶ WHAT EACH SHEET DOES
B17: • Dashboard — 4 KPI cards (pipeline, attainment, win rate, avg deal), pipeline funnel by stage, rep leaderboard with progress bars. Print landscape for one-page reports.
B19: • Deal Pipeline — Every open and closed deal. Includes a small STAGE CONFIG section at the top where you customize win probabilities per stage. Stage names drive dropdowns everywhere.
B21: • Rep Performance — Per-rep rollup: open deals, pipeline value, won deals, revenue, attainment %. Color-coded attainment (green/yellow/red). Feeds the Dashboard leaderboard.
B23: • Quotas — Rep list and monthly quota assignments. Add or remove reps as your team changes.
B25: • Historical Trends — 12-month rolling team performance: revenue, deals won, win rate, avg deal, cycle length. Current month pulls live from Deal Pipeline.
B29: ▶ TIPS
B31: • Update Deal Pipeline weekly (or after every won deal) — the dashboard is only as current as your data.
B32: • Change a deal stage on the Deal Pipeline sheet and watch the funnel + leaderboard update instantly.
B33: • Log closed-lost deals too — they're needed for accurate win-rate calculation.
B34: • For weekly team meetings: print the Dashboard sheet (already configured landscape, fit-to-page) or save as PDF.
B35: • Customize stage names on the Stage Config section (Deal Pipeline sheet, rows 5-11). The dropdowns everywhere else update automatically.
... B39: Built by Sheets & Cells. Free for personal & commercial use. sheetsandcells.com

Sheet Dashboard
A1: Q1 2026 SALES PERFORMANCE
A2: ="Period: " & TEXT(TODAY(),"mmmm yyyy") & " · Auto-updated from Deal Pipeline" -> Period: July 2026 · Auto-updated from Deal Pipeline
B4: TOTAL PIPELINE | D4: MONTHLY ATTAINMENT | F4: WIN RATE | H4: AVG DEAL SIZE
B5: =SUM(DealWeighted)-SUMIFS(DealWeighted,DealStages,"Closed Won")-SUMIFS(DealWeighted,DealStages,"Closed Lost") -> 602750 | D5: =IFERROR(SUMIFS(DealValues,DealStages,"Closed Won",DealCloseActual,">="&DATE(2026,1,1),DealCloseActual,"<="&DATE(2026,1,31))/SUM(Quotas!E5:E14),0) -> 0.92311412 | F5: =IFERROR(COUNTIF(DealStages,"Closed Won")/(COUNTIF(DealStages,"Closed Won")+COUNTIF(DealStages,"Closed Lost")),0) -> 0.82352941 | H5: =IFERROR(AVERAGEIF(DealStages,"Closed Won",DealValues),0) -> 136357.14
B7: ="Weighted forecast · " & COUNTIFS(DealStages,"<>Closed Won",DealStages,"<>Closed Lost",DealStages,"<>") & " open deals" -> Weighted forecast · 13 open deals | D7: =TEXT(SUMIFS(DealValues,DealStages,"Closed Won",DealCloseActual,">="&DATE(2026,1,1),DealCloseActual,"<="&DATE(2026,1,31)),"$#,##0")&" of "&TEXT(SUM(Quotas!E5:E14),"$#,##0") -> $1,909,000 of $2,068,000 | F7: =COUNTIF(DealStages,"Closed Won")&" won of "&(COUNTIF(DealStages,"Closed Won")+COUNTIF(DealStages,"Closed Lost"))&" decided" -> 14 won of 17 decided | H7: ="Across closed-won deals" -> Across closed-won deals
B9: ▶ PIPELINE BY STAGE
B10: Stage | C10: Deals | D10: Total Value | E10: Value Distribution (bar shows relative size) | I10: Weighted
B11: Prospecting | C11: =COUNTIF(DealStages,"Prospecting") -> 3 | D11: =SUMIFS(DealValues,DealStages,"Prospecting") -> 195000 | E11: =SUMIFS(DealValues,DealStages,"Prospecting") -> 195000 | I11: =SUMIFS(DealWeighted,DealStages,"Prospecting") -> 29250
B12: Qualification | C12: =COUNTIF(DealStages,"Qualification") -> 4 | D12: =SUMIFS(DealValues,DealStages,"Qualification") -> 200000 | E12: =SUMIFS(DealValues,DealStages,"Qualification") -> 200000 | I12: =SUMIFS(DealWeighted,DealStages,"Qualification") -> 56000
B13: Proposal | C13: =COUNTIF(DealStages,"Proposal") -> 3 | D13: =SUMIFS(DealValues,DealStages,"Proposal") -> 270000 | E13: =SUMIFS(DealValues,DealStages,"Proposal") -> 270000 | I13: =SUMIFS(DealWeighted,DealStages,"Proposal") -> 121500
B14: Negotiation | C14: =COUNTIF(DealStages,"Negotiation") -> 3 | D14: =SUMIFS(DealValues,DealStages,"Negotiation") -> 550000 | E14: =SUMIFS(DealValues,DealStages,"Negotiation") -> 550000 | I14: =SUMIFS(DealWeighted,DealStages,"Negotiation") -> 396000
B15: Closed Won | C15: =COUNTIF(DealStages,"Closed Won") -> 14 | D15: =SUMIFS(DealValues,DealStages,"Closed Won") -> 1909000 | E15: =SUMIFS(DealValues,DealStages,"Closed Won") -> 1909000 | I15: =SUMIFS(DealWeighted,DealStages,"Closed Won") -> 1909000
B17: ▶ REP LEADERBOARD (Quarter to Date)
B18: Rep | C18: Rank | D18: Revenue | E18: Quota Progress | I18: Attainment
B19: ='Rep Performance'!B5 -> Sarah Chen | C19: =RANK(D19,$D$19:$D$24) -> 1 | D19: ='Rep Performance'!F5 -> 486000 | E19: ='Rep Performance'!H5 -> 1.4507463 | I19: ='Rep Performance'!H5 -> 1.4507463
B20: ='Rep Performance'!B6 -> Marcus Rivera | C20: =RANK(D20,$D$19:$D$24) -> 2 | D20: ='Rep Performance'!F6 -> 412000 | E20: ='Rep Performance'!H6 -> 1.1805158 | I20: ='Rep Performance'!H6 -> 1.1805158
B21: ='Rep Performance'!B7 -> Priya Kumar | C21: =RANK(D21,$D$19:$D$24) -> 3 | D21: ='Rep Performance'!F7 -> 321000 | E21: ='Rep Performance'!H7 -> 0.91977077 | I21: ='Rep Performance'!H7 -> 0.91977077
B22: ='Rep Performance'!B8 -> Jake Morris | C22: =RANK(D22,$D$19:$D$24) -> 4 | D22: ='Rep Performance'!F8 -> 291000 | E22: ='Rep Performance'!H8 -> 0.86865672 | I22: ='Rep Performance'!H8 -> 0.86865672
B23: ='Rep Performance'!B9 -> Diana Lee | C23: =RANK(D23,$D$19:$D$24) -> 5 | D23: ='Rep Performance'!F9 -> 256000 | E23: ='Rep Performance'!H9 -> 0.72934473 | I23: ='Rep Performance'!H9 -> 0.72934473
B24: ='Rep Performance'!B10 -> Tom Baxter | C24: =RANK(D24,$D$19:$D$24) -> 6 | D24: ='Rep Performance'!F10 -> 143000 | E24: ='Rep Performance'!H10 -> 0.40974212 | I24: ='Rep Performance'!H10 -> 0.40974212
B27: 💡 All numbers pull from Deal Pipeline and Quotas. Change any deal stage or quota — this dashboard updates instantly.

Sheet Deal Pipeline
A1: DEAL PIPELINE
A2: Log every open and closed deal here. The Dashboard, Rep Performance, and Historical Trends sheets all read from this list.
A4: ▶ STAGE CONFIG (customize probabilities per stage)
A5: Stage Name | B5: Default Probability | C5: Order | D5: Type
A6: Prospecting | B6: 0.15 | C6: 1 | D6: Open
A7: Qualification | B7: 0.28 | C7: 2 | D7: Open
A8: Proposal | B8: 0.45 | C8: 3 | D8: Open
A9: Negotiation | B9: 0.72 | C9: 4 | D9: Open
A10: Closed Won | B10: 1 | C10: 5 | D10: Closed
A11: Closed Lost | B11: 0 | C11: 6 | D11: Closed
A13: ▶ DEALS
A14: Deal Name | B14: Client Company | C14: Rep | D14: Stage | E14: Value ($) | F14: Prob (%) | G14: Weighted ($) | H14: Close Est. | I14: Close Actual | J14: Notes
A15: Acme Corp — Enterprise renewal | B15: Acme Corp | C15: Sarah Chen | D15: Closed Won | E15: 205000 | F15: =IFERROR(VLOOKUP(D15,StageProbTable,2,FALSE()),0) -> 1 | G15: =E15*F15 -> 205000 | H15: 46044 | I15: 46044
A16: Northline Group — Global rollout | B16: Northline Group | C16: Sarah Chen | D16: Closed Won | E16: 180000 | F16: =IFERROR(VLOOKUP(D16,StageProbTable,2,FALSE()),0) -> 1 | G16: =E16*F16 -> 180000 | H16: 46040 | I16: 46040
A17: Riverside Health — Analytics module | B17: Riverside Health | C17: Sarah Chen | D17: Closed Won | E17: 101000 | F17: =IFERROR(VLOOKUP(D17,StageProbTable,2,FALSE()),0) -> 1 | G17: =E17*F17 -> 101000 | H17: 46030 | I17: 46030
A18: Bloom Retail — Multi-store license | B18: Bloom Retail | C18: Marcus Rivera | D18: Closed Won | E18: 175000 | F18: =IFERROR(VLOOKUP(D18,StageProbTable,2,FALSE()),0) -> 1 | G18: =E18*F18 -> 175000 | H18: 46047 | I18: 46047
A19: Vermont Bakery Co — Ops suite | B19: Vermont Bakery Co | C19: Marcus Rivera | D19: Closed Won | E19: 142000 | F19: =IFERROR(VLOOKUP(D19,StageProbTable,2,FALSE()),0) -> 1 | G19: =E19*F19 -> 142000 | H19: 46038 | I19: 46038
A20: Peakstone Auto — Fleet software | B20: Peakstone Auto | C20: Marcus Rivera | D20: Closed Won | E20: 95000 | F20: =IFERROR(VLOOKUP(D20,StageProbTable,2,FALSE()),0) -> 1 | G20: =E20*F20 -> 95000 | H20: 46027 | I20: 46027
A21: Chapman Legal — Practice suite | B21: Chapman Legal | C21: Priya Kumar | D21: Closed Won | E21: 198000 | F21: =IFERROR(VLOOKUP(D21,StageProbTable,2,FALSE()),0) -> 1 | G21: =E21*F21 -> 198000 | H21: 46049 | I21: 46049
A22: Meridian Consulting — Team plan | B22: Meridian Consulting | C22: Priya Kumar | D22: Closed Won | E22: 123000 | F22: =IFERROR(VLOOKUP(D22,StageProbTable,2,FALSE()),0) -> 1 | G22: =E22*F22 -> 123000 | H22: 46034 | I22: 46034
A23: Delta Studios — Team of 24 | B23: Delta Studios | C23: Jake Morris | D23: Closed Won | E23: 130000 | F23: =IFERROR(VLOOKUP(D23,StageProbTable,2,FALSE()),0) -> 1 | G23: =E23*F23 -> 130000 | H23: 46042 | I23: 46042
A24: Foothill Ventures — Portfolio license | B24: Foothill Ventures | C24: Jake Morris | D24: Closed Won | E24: 108000 | F24: =IFERROR(VLOOKUP(D24,StageProbTable,2,FALSE()),0) -> 1 | G24: =E24*F24 -> 108000 | H24: 46036 | I24: 46036
A25: Sunrise Community College — Suite | B25: Sunrise Community College | C25: Jake Morris | D25: Closed Won | E25: 53000 | F25: =IFERROR(VLOOKUP(D25,StageProbTable,2,FALSE()),0) -> 1 | G25: =E25*F25 -> 53000 | H25: 46029 | I25: 46029
A26: Everest Media — Content package | B26: Everest Media | C26: Diana Lee | D26: Closed Won | E26: 155000 | F26: =IFERROR(VLOOKUP(D26,StageProbTable,2,FALSE()),0) -> 1 | G26: =E26*F26 -> 155000 | H26: 46044 | I26: 46044
... A31: Ridgeway Bank — no budget | B31: Ridgeway Bank | C31: Tom Baxter | D31: Closed Lost | E31: 65000 | F31: =IFERROR(VLOOKUP(D31,StageProbTable,2,FALSE()),0) -> 0 | G31: =E31*F31 -> 0 | H31: 46028 | I31: 46028
A32: Solstice Advisors — Contract review | B32: Solstice Advisors | C32: Sarah Chen | D32: Negotiation | E32: 185000 | F32: =IFERROR(VLOOKUP(D32,StageProbTable,2,FALSE()),0) -> 0.72 | G32: =E32*F32 -> 133200 | H32: 46065
A33: Harbor Digital — Legal in progress | B33: Harbor Digital | C33: Marcus Rivera | D33: Negotiation | E33: 145000 | F33: =IFERROR(VLOOKUP(D33,StageProbTable,2,FALSE()),0) -> 0.72 | G33: =E33*F33 -> 104400 | H33: 46071
A34: Ironwood Financial — Final terms | B34: Ironwood Financial | C34: Priya Kumar | D34: Negotiation | E34: 220000 | F34: =IFERROR(VLOOKUP(D34,StageProbTable,2,FALSE()),0) -> 0.72 | G34: =E34*F34 -> 158400 | H34: 46067
A35: Silverpeak Foods — Proposal sent | B35: Silverpeak Foods | C35: Sarah Chen | D35: Proposal | E35: 110000 | F35: =IFERROR(VLOOKUP(D35,StageProbTable,2,FALSE()),0) -> 0.45 | G35: =E35*F35 -> 49500 | H35: 46081
A36: Meadowlark Media — Q1 evaluation | B36: Meadowlark Media | C36: Diana Lee | D36: Proposal | E36: 88000 | F36: =IFERROR(VLOOKUP(D36,StageProbTable,2,FALSE()),0) -> 0.45 | G36: =E36*F36 -> 39600 | H36: 46086
A37: Coastline Insurance — Pricing sent | B37: Coastline Insurance | C37: Jake Morris | D37: Proposal | E37: 72000 | F37: =IFERROR(VLOOKUP(D37,StageProbTable,2,FALSE()),0) -> 0.45 | G37: =E37*F37 -> 32400 | H37: 46091
A38: Ridgeline Marketing — Fit call scheduled | B38: Ridgeline Marketing | C38: Marcus Rivera | D38: Qualification | E38: 65000 | F38: =IFERROR(VLOOKUP(D38,StageProbTable,2,FALSE()),0) -> 0.28 | G38: =E38*F38 -> 18200 | H38: 46096
A39: Old Mill Coffee — Timeline discussion | B39: Old Mill Coffee | C39: Priya Kumar | D39: Qualification | E39: 38000 | F39: =IFERROR(VLOOKUP(D39,StageProbTable,2,FALSE()),0) -> 0.28 | G39: =E39*F39 -> 10640 | H39: 46101
A40: Beacon Studios — Budget check | B40: Beacon Studios | C40: Diana Lee | D40: Qualification | E40: 52000 | F40: =IFERROR(VLOOKUP(D40,StageProbTable,2,FALSE()),0) -> 0.28 | G40: =E40*F40 -> 14560 | H40: 46103
A41: Cypress Consulting — POC discussion | B41: Cypress Consulting | C41: Tom Baxter | D41: Qualification | E41: 45000 | F41: =IFERROR(VLOOKUP(D41,StageProbTable,2,FALSE()),0) -> 0.28 | G41: =E41*F41 -> 12600 | H41: 46106
A42: Lakeside Ventures — Cold outreach | B42: Lakeside Ventures | C42: Sarah Chen | D42: Prospecting | E42: 85000 | F42: =IFERROR(VLOOKUP(D42,StageProbTable,2,FALSE()),0) -> 0.15 | G42: =E42*F42 -> 12750 | H42: 46111
A43: Grandview Realty — Referral | B43: Grandview Realty | C43: Marcus Rivera | D43: Prospecting | E43: 62000 | F43: =IFERROR(VLOOKUP(D43,StageProbTable,2,FALSE()),0) -> 0.15 | G43: =E43*F43 -> 9300 | H43: 46111
A44: Alpine Analytics — Inbound lead | B44: Alpine Analytics | C44: Jake Morris | D44: Prospecting | E44: 48000 | F44: =IFERROR(VLOOKUP(D44,StageProbTable,2,FALSE()),0) -> 0.15 | G44: =E44*F44 -> 7200 | H44: 46117
F45: =IF(D45="","",IFERROR(VLOOKUP(D45,StageProbTable,2,FALSE()),0)) | G45: =IF(OR(E45="",F45=""),"",E45*F45)
F46: =IF(D46="","",IFERROR(VLOOKUP(D46,StageProbTable,2,FALSE()),0)) | G46: =IF(OR(E46="",F46=""),"",E46*F46)
...

Sheet Rep Performance
A1: REP PERFORMANCE
A2: Per-rep rollup of deals worked, closed, revenue, and attainment. All numbers calculated from the Deal Pipeline sheet.
A4: # | B4: Rep Name | C4: Open Deals | D4: Pipeline $ | E4: Won Deals | F4: Revenue $ | G4: Monthly Quota | H4: Attainment
A5: =IF(Quotas!B5="","",Quotas!A5) -> 1 | B5: =IF(Quotas!B5="","",Quotas!B5) -> Sarah Chen | C5: =IF(B5="","",COUNTIFS(DealReps,B5)-COUNTIFS(DealReps,B5,DealStages,"Closed Won")-COUNTIFS(DealReps,B5,DealStages,"Closed Lost")) -> 3 | D5: =IF(B5="","",SUMIFS(DealValues,DealReps,B5)-SUMIFS(DealValues,DealReps,B5,DealStages,"Closed Won")-SUMIFS(DealValues,DealReps,B5,DealStages,"Closed Lost")) -> 380000 | E5: =IF(B5="","",COUNTIFS(DealReps,B5,DealStages,"Closed Won")) -> 3 | F5: =IF(B5="","",SUMIFS(DealValues,DealReps,B5,DealStages,"Closed Won")) -> 486000 | G5: =IF(B5="","",Quotas!E5) -> 335000 | H5: =IFERROR(F5/G5,0) -> 1.4507463
A6: =IF(Quotas!B6="","",Quotas!A6) -> 2 | B6: =IF(Quotas!B6="","",Quotas!B6) -> Marcus Rivera | C6: =IF(B6="","",COUNTIFS(DealReps,B6)-COUNTIFS(DealReps,B6,DealStages,"Closed Won")-COUNTIFS(DealReps,B6,DealStages,"Closed Lost")) -> 3 | D6: =IF(B6="","",SUMIFS(DealValues,DealReps,B6)-SUMIFS(DealValues,DealReps,B6,DealStages,"Closed Won")-SUMIFS(DealValues,DealReps,B6,DealStages,"Closed Lost")) -> 272000 | E6: =IF(B6="","",COUNTIFS(DealReps,B6,DealStages,"Closed Won")) -> 3 | F6: =IF(B6="","",SUMIFS(DealValues,DealReps,B6,DealStages,"Closed Won")) -> 412000 | G6: =IF(B6="","",Quotas!E6) -> 349000 | H6: =IFERROR(F6/G6,0) -> 1.1805158
A7: =IF(Quotas!B7="","",Quotas!A7) -> 3 | B7: =IF(Quotas!B7="","",Quotas!B7) -> Priya Kumar | C7: =IF(B7="","",COUNTIFS(DealReps,B7)-COUNTIFS(DealReps,B7,DealStages,"Closed Won")-COUNTIFS(DealReps,B7,DealStages,"Closed Lost")) -> 2 | D7: =IF(B7="","",SUMIFS(DealValues,DealReps,B7)-SUMIFS(DealValues,DealReps,B7,DealStages,"Closed Won")-SUMIFS(DealValues,DealReps,B7,DealStages,"Closed Lost")) -> 258000 | E7: =IF(B7="","",COUNTIFS(DealReps,B7,DealStages,"Closed Won")) -> 2 | F7: =IF(B7="","",SUMIFS(DealValues,DealReps,B7,DealStages,"Closed Won")) -> 321000 | G7: =IF(B7="","",Quotas!E7) -> 349000 | H7: =IFERROR(F7/G7,0) -> 0.91977077
A8: =IF(Quotas!B8="","",Quotas!A8) -> 4 | B8: =IF(Quotas!B8="","",Quotas!B8) -> Jake Morris | C8: =IF(B8="","",COUNTIFS(DealReps,B8)-COUNTIFS(DealReps,B8,DealStages,"Closed Won")-COUNTIFS(DealReps,B8,DealStages,"Closed Lost")) -> 2 | D8: =IF(B8="","",SUMIFS(DealValues,DealReps,B8)-SUMIFS(DealValues,DealReps,B8,DealStages,"Closed Won")-SUMIFS(DealValues,DealReps,B8,DealStages,"Closed Lost")) -> 120000 | E8: =IF(B8="","",COUNTIFS(DealReps,B8,DealStages,"Closed Won")) -> 3 | F8: =IF(B8="","",SUMIFS(DealValues,DealReps,B8,DealStages,"Closed Won")) -> 291000 | G8: =IF(B8="","",Quotas!E8) -> 335000 | H8: =IFERROR(F8/G8,0) -> 0.86865672
A9: =IF(Quotas!B9="","",Quotas!A9) -> 5 | B9: =IF(Quotas!B9="","",Quotas!B9) -> Diana Lee | C9: =IF(B9="","",COUNTIFS(DealReps,B9)-COUNTIFS(DealReps,B9,DealStages,"Closed Won")-COUNTIFS(DealReps,B9,DealStages,"Closed Lost")) -> 2 | D9: =IF(B9="","",SUMIFS(DealValues,DealReps,B9)-SUMIFS(DealValues,DealReps,B9,DealStages,"Closed Won")-SUMIFS(DealValues,DealReps,B9,DealStages,"Closed Lost")) -> 140000 | E9: =IF(B9="","",COUNTIFS(DealReps,B9,DealStages,"Closed Won")) -> 2 | F9: =IF(B9="","",SUMIFS(DealValues,DealReps,B9,DealStages,"Closed Won")) -> 256000 | G9: =IF(B9="","",Quotas!E9) -> 351000 | H9: =IFERROR(F9/G9,0) -> 0.72934473
A10: =IF(Quotas!B10="","",Quotas!A10) -> 6 | B10: =IF(Quotas!B10="","",Quotas!B10) -> Tom Baxter | C10: =IF(B10="","",COUNTIFS(DealReps,B10)-COUNTIFS(DealReps,B10,DealStages,"Closed Won")-COUNTIFS(DealReps,B10,DealStages,"Closed Lost")) -> 1 | D10: =IF(B10="","",SUMIFS(DealValues,DealReps,B10)-SUMIFS(DealValues,DealReps,B10,DealStages,"Closed Won")-SUMIFS(DealValues,DealReps,B10,DealStages,"Closed Lost")) -> 45000 | E10: =IF(B10="","",COUNTIFS(DealReps,B10,DealStages,"Closed Won")) -> 1 | F10: =IF(B10="","",SUMIFS(DealValues,DealReps,B10,DealStages,"Closed Won")) -> 143000 | G10: =IF(B10="","",Quotas!E10) -> 349000 | H10: =IFERROR(F10/G10,0) -> 0.40974212
A11: =IF(Quotas!B11="","",Quotas!A11) | B11: =IF(Quotas!B11="","",Quotas!B11) | C11: =IF(B11="","",COUNTIFS(DealReps,B11)-COUNTIFS(DealReps,B11,DealStages,"Closed Won")-COUNTIFS(DealReps,B11,DealStages,"Closed Lost")) | D11: =IF(B11="","",SUMIFS(DealValues,DealReps,B11)-SUMIFS(DealValues,DealReps,B11,DealStages,"Closed Won")-SUMIFS(DealValues,DealReps,B11,DealStages,"Closed Lost")) | E11: =IF(B11="","",COUNTIFS(DealReps,B11,DealStages,"Closed Won")) | F11: =IF(B11="","",SUMIFS(DealValues,DealReps,B11,DealStages,"Closed Won")) | G11: =IF(B11="","",Quotas!E11) | H11: =IFERROR(F11/G11,0) -> 0
A12: =IF(Quotas!B12="","",Quotas!A12) | B12: =IF(Quotas!B12="","",Quotas!B12) | C12: =IF(B12="","",COUNTIFS(DealReps,B12)-COUNTIFS(DealReps,B12,DealStages,"Closed Won")-COUNTIFS(DealReps,B12,DealStages,"Closed Lost")) | D12: =IF(B12="","",SUMIFS(DealValues,DealReps,B12)-SUMIFS(DealValues,DealReps,B12,DealStages,"Closed Won")-SUMIFS(DealValues,DealReps,B12,DealStages,"Closed Lost")) | E12: =IF(B12="","",COUNTIFS(DealReps,B12,DealStages,"Closed Won")) | F12: =IF(B12="","",SUMIFS(DealValues,DealReps,B12,DealStages,"Closed Won")) | G12: =IF(B12="","",Quotas!E12) | H12: =IFERROR(F12/G12,0) -> 0
A13: =IF(Quotas!B13="","",Quotas!A13) | B13: =IF(Quotas!B13="","",Quotas!B13) | C13: =IF(B13="","",COUNTIFS(DealReps,B13)-COUNTIFS(DealReps,B13,DealStages,"Closed Won")-COUNTIFS(DealReps,B13,DealStages,"Closed Lost")) | D13: =IF(B13="","",SUMIFS(DealValues,DealReps,B13)-SUMIFS(DealValues,DealReps,B13,DealStages,"Closed Won")-SUMIFS(DealValues,DealReps,B13,DealStages,"Closed Lost")) | E13: =IF(B13="","",COUNTIFS(DealReps,B13,DealStages,"Closed Won")) | F13: =IF(B13="","",SUMIFS(DealValues,DealReps,B13,DealStages,"Closed Won")) | G13: =IF(B13="","",Quotas!E13) | H13: =IFERROR(F13/G13,0) -> 0
A14: =IF(Quotas!B14="","",Quotas!A14) | B14: =IF(Quotas!B14="","",Quotas!B14) | C14: =IF(B14="","",COUNTIFS(DealReps,B14)-COUNTIFS(DealReps,B14,DealStages,"Closed Won")-COUNTIFS(DealReps,B14,DealStages,"Closed Lost")) | D14: =IF(B14="","",SUMIFS(DealValues,DealReps,B14)-SUMIFS(DealValues,DealReps,B14,DealStages,"Closed Won")-SUMIFS(DealValues,DealReps,B14,DealStages,"Closed Lost")) | E14: =IF(B14="","",COUNTIFS(DealReps,B14,DealStages,"Closed Won")) | F14: =IF(B14="","",SUMIFS(DealValues,DealReps,B14,DealStages,"Closed Won")) | G14: =IF(B14="","",Quotas!E14) | H14: =IFERROR(F14/G14,0) -> 0
B16: TEAM TOTAL | C16: =SUM(C5:C14) -> 13 | D16: =SUM(D5:D14) -> 1215000 | E16: =SUM(E5:E14) -> 14 | F16: =SUM(F5:F14) -> 1909000 | G16: =SUM(G5:G14) -> 2068000 | H16: =IFERROR(F16/G16,0) -> 0.92311412

Sheet Quotas
A1: QUOTAS
A2: Set each rep's monthly quota. The Dashboard reads these values for the leaderboard progress bars and team attainment KPI.
A4: # | B4: Rep Name | C4: Email | D4: Territory | E4: Monthly Quota | F4: Status
A5: 1 | B5: Sarah Chen | C5: sarah.chen@example.com | D5: West / Enterprise | E5: 335000 | F5: Active
A6: 2 | B6: Marcus Rivera | C6: marcus.rivera@example.com | D6: East / Mid-market | E6: 349000 | F6: Active
A7: 3 | B7: Priya Kumar | C7: priya.kumar@example.com | D7: Central / Mid-market | E7: 349000 | F7: Active
A8: 4 | B8: Jake Morris | C8: jake.morris@example.com | D8: West / SMB | E8: 335000 | F8: Active
A9: 5 | B9: Diana Lee | C9: diana.lee@example.com | D9: East / SMB | E9: 351000 | F9: Active
A10: 6 | B10: Tom Baxter | C10: tom.baxter@example.com | D10: Central / SMB | E10: 349000 | F10: Ramping
B15: TEAM TOTAL | E15: =SUM(E5:E14) -> 2068000

Sheet Historical Trends
A1: HISTORICAL TRENDS
A2: 12-month rolling view of team performance. Backfill with your historical data or let this fill in as months pass.
A4: Month | B4: Revenue | C4: Deals Won | D4: Win Rate | E4: Avg Deal | F4: Cycle (days)
A5: 45689 | B5: 1250000 | C5: 24 | D5: 0.23 | E5: 52083 | F5: 68
A6: 45717 | B6: 1340000 | C6: 26 | D6: 0.24 | E6: 51538 | F6: 65
A7: 45748 | B7: 1180000 | C7: 22 | D7: 0.22 | E7: 53636 | F7: 71
A8: 45778 | B8: 1420000 | C8: 28 | D8: 0.25 | E8: 50714 | F8: 63
A9: 45809 | B9: 1510000 | C9: 29 | D9: 0.25 | E9: 52069 | F9: 62
A10: 45839 | B10: 1380000 | C10: 27 | D10: 0.24 | E10: 51111 | F10: 66
A11: 45870 | B11: 1450000 | C11: 28 | D11: 0.25 | E11: 51786 | F11: 64
A12: 45901 | B12: 1620000 | C12: 31 | D12: 0.26 | E12: 52258 | F12: 61
A13: 45931 | B13: 1580000 | C13: 30 | D13: 0.26 | E13: 52667 | F13: 63
A14: 45962 | B14: 1720000 | C14: 33 | D14: 0.27 | E14: 52121 | F14: 60
A15: 45992 | B15: 1650000 | C15: 32 | D15: 0.26 | E15: 51563 | F15: 62
A16: 46023 | B16: =SUMIFS(DealValues,DealStages,"Closed Won",DealCloseActual,">="&DATE(2026,1,1),DealCloseActual,"<="&DATE(2026,1,31)) -> 1909000 | C16: =COUNTIFS(DealStages,"Closed Won",DealCloseActual,">="&DATE(2026,1,1),DealCloseActual,"<="&DATE(2026,1,31)) -> 14 | D16: =IFERROR(C16/(C16+COUNTIFS(DealStages,"Closed Lost",DealCloseActual,">="&DATE(2026,1,1),DealCloseActual,"<="&DATE(2026,1,31))),0) -> 0.82352941 | E16: =IFERROR(B16/C16,0) -> 136357.14 | F16: 58
A18: 12-MONTH SUMMARY
A19: Total Revenue (YTD) | B19: =SUM(B5:B16) -> 18009000
A20: Total Deals Won | B20: =SUM(C5:C16) -> 324
A21: Avg Win Rate | B21: =AVERAGE(D5:D16) -> 0.29612745
A22: Avg Deal Size | B22: =IFERROR(B18/C19,0) -> 0
