Workbook

Sheet Overview
C1: SALES & OPERATIONS OVERVIEW
C2: Revenue, depletion, receivables and sales performance.
A5: REPORTING YEAR | B5: 2026 | D5: Use Lagom → Run Check when you want a concise data-quality check.
A7: REVENUE | E7: CASES | I7: GROSS PROFIT | M7: GROSS MARGIN
A8: =SUM(Invoices!$L$9:$L$108) | E8: =SUM(Invoices!$M$9:$M$108) | I8: =SUM(Invoices!$O$9:$O$108) | M8: =IFERROR(SUM(Invoices!$O$9:$O$108)/SUM(Invoices!$L$9:$L$108),0)
A11: OPEN AR | E11: OVERDUE AR | I11: PAID REVENUE | M11: NEEDS ATTENTION
A12: =SUM(Invoices!$Q$9:$Q$108) | E12: =SUMIFS(Invoices!$Q$9:$Q$108,Invoices!$T$9:$T$108,">0") | I12: =SUMIFS(Invoices!$L$9:$L$108,Invoices!$S$9:$S$108,"Paid") | M12: =COUNTIF(Invoices!$W$9:$W$108,"REVIEW")+COUNTIF(Depletion!$O$9:$O$208,"REVIEW")
A16: Monthly Performance | F16: Revenue Trend | N16: AR Aging
A18: Month | B18: Revenue | C18: Cases | D18: Gross Profit | E18: Margin | N18: Bucket | O18: Invoices | P18: Amount Due
A19: Jan | B19: =SUMIFS(Invoices!$L$9:$L$108,Invoices!$B$9:$B$108,">="&DATE($B$5,1,1),Invoices!$B$9:$B$108,"<"&DATE($B$5,2,1)) | C19: =SUMIFS(Invoices!$M$9:$M$108,Invoices!$B$9:$B$108,">="&DATE($B$5,1,1),Invoices!$B$9:$B$108,"<"&DATE($B$5,2,1)) | D19: =SUMIFS(Invoices!$O$9:$O$108,Invoices!$B$9:$B$108,">="&DATE($B$5,1,1),Invoices!$B$9:$B$108,"<"&DATE($B$5,2,1)) | E19: =IFERROR(D19/B19,0) | N19: Current | O19: =COUNTIFS(Invoices!$U$9:$U$108,N19,Invoices!$Q$9:$Q$108,">0") | P19: =SUMIF(Invoices!$U$9:$U$108,N19,Invoices!$Q$9:$Q$108)
A20: Feb | B20: =SUMIFS(Invoices!$L$9:$L$108,Invoices!$B$9:$B$108,">="&DATE($B$5,2,1),Invoices!$B$9:$B$108,"<"&DATE($B$5,3,1)) | C20: =SUMIFS(Invoices!$M$9:$M$108,Invoices!$B$9:$B$108,">="&DATE($B$5,2,1),Invoices!$B$9:$B$108,"<"&DATE($B$5,3,1)) | D20: =SUMIFS(Invoices!$O$9:$O$108,Invoices!$B$9:$B$108,">="&DATE($B$5,2,1),Invoices!$B$9:$B$108,"<"&DATE($B$5,3,1)) | E20: =IFERROR(D20/B20,0) | N20: 1-30 | O20: =COUNTIFS(Invoices!$U$9:$U$108,N20,Invoices!$Q$9:$Q$108,">0") | P20: =SUMIF(Invoices!$U$9:$U$108,N20,Invoices!$Q$9:$Q$108)
A21: Mar | B21: =SUMIFS(Invoices!$L$9:$L$108,Invoices!$B$9:$B$108,">="&DATE($B$5,3,1),Invoices!$B$9:$B$108,"<"&DATE($B$5,4,1)) | C21: =SUMIFS(Invoices!$M$9:$M$108,Invoices!$B$9:$B$108,">="&DATE($B$5,3,1),Invoices!$B$9:$B$108,"<"&DATE($B$5,4,1)) | D21: =SUMIFS(Invoices!$O$9:$O$108,Invoices!$B$9:$B$108,">="&DATE($B$5,3,1),Invoices!$B$9:$B$108,"<"&DATE($B$5,4,1)) | E21: =IFERROR(D21/B21,0) | N21: 31-60 | O21: =COUNTIFS(Invoices!$U$9:$U$108,N21,Invoices!$Q$9:$Q$108,">0") | P21: =SUMIF(Invoices!$U$9:$U$108,N21,Invoices!$Q$9:$Q$108)
A22: Apr | B22: =SUMIFS(Invoices!$L$9:$L$108,Invoices!$B$9:$B$108,">="&DATE($B$5,4,1),Invoices!$B$9:$B$108,"<"&DATE($B$5,5,1)) | C22: =SUMIFS(Invoices!$M$9:$M$108,Invoices!$B$9:$B$108,">="&DATE($B$5,4,1),Invoices!$B$9:$B$108,"<"&DATE($B$5,5,1)) | D22: =SUMIFS(Invoices!$O$9:$O$108,Invoices!$B$9:$B$108,">="&DATE($B$5,4,1),Invoices!$B$9:$B$108,"<"&DATE($B$5,5,1)) | E22: =IFERROR(D22/B22,0) | N22: 61-90 | O22: =COUNTIFS(Invoices!$U$9:$U$108,N22,Invoices!$Q$9:$Q$108,">0") | P22: =SUMIF(Invoices!$U$9:$U$108,N22,Invoices!$Q$9:$Q$108)
A23: May | B23: =SUMIFS(Invoices!$L$9:$L$108,Invoices!$B$9:$B$108,">="&DATE($B$5,5,1),Invoices!$B$9:$B$108,"<"&DATE($B$5,6,1)) | C23: =SUMIFS(Invoices!$M$9:$M$108,Invoices!$B$9:$B$108,">="&DATE($B$5,5,1),Invoices!$B$9:$B$108,"<"&DATE($B$5,6,1)) | D23: =SUMIFS(Invoices!$O$9:$O$108,Invoices!$B$9:$B$108,">="&DATE($B$5,5,1),Invoices!$B$9:$B$108,"<"&DATE($B$5,6,1)) | E23: =IFERROR(D23/B23,0) | N23: 90+ | O23: =COUNTIFS(Invoices!$U$9:$U$108,N23,Invoices!$Q$9:$Q$108,">0") | P23: =SUMIF(Invoices!$U$9:$U$108,N23,Invoices!$Q$9:$Q$108)
A24: Jun | B24: =SUMIFS(Invoices!$L$9:$L$108,Invoices!$B$9:$B$108,">="&DATE($B$5,6,1),Invoices!$B$9:$B$108,"<"&DATE($B$5,7,1)) | C24: =SUMIFS(Invoices!$M$9:$M$108,Invoices!$B$9:$B$108,">="&DATE($B$5,6,1),Invoices!$B$9:$B$108,"<"&DATE($B$5,7,1)) | D24: =SUMIFS(Invoices!$O$9:$O$108,Invoices!$B$9:$B$108,">="&DATE($B$5,6,1),Invoices!$B$9:$B$108,"<"&DATE($B$5,7,1)) | E24: =IFERROR(D24/B24,0)
A25: Jul | B25: =SUMIFS(Invoices!$L$9:$L$108,Invoices!$B$9:$B$108,">="&DATE($B$5,7,1),Invoices!$B$9:$B$108,"<"&DATE($B$5,8,1)) | C25: =SUMIFS(Invoices!$M$9:$M$108,Invoices!$B$9:$B$108,">="&DATE($B$5,7,1),Invoices!$B$9:$B$108,"<"&DATE($B$5,8,1)) | D25: =SUMIFS(Invoices!$O$9:$O$108,Invoices!$B$9:$B$108,">="&DATE($B$5,7,1),Invoices!$B$9:$B$108,"<"&DATE($B$5,8,1)) | E25: =IFERROR(D25/B25,0) | N25: Needs Attention
A26: Aug | B26: =SUMIFS(Invoices!$L$9:$L$108,Invoices!$B$9:$B$108,">="&DATE($B$5,8,1),Invoices!$B$9:$B$108,"<"&DATE($B$5,9,1)) | C26: =SUMIFS(Invoices!$M$9:$M$108,Invoices!$B$9:$B$108,">="&DATE($B$5,8,1),Invoices!$B$9:$B$108,"<"&DATE($B$5,9,1)) | D26: =SUMIFS(Invoices!$O$9:$O$108,Invoices!$B$9:$B$108,">="&DATE($B$5,8,1),Invoices!$B$9:$B$108,"<"&DATE($B$5,9,1)) | E26: =IFERROR(D26/B26,0)
A27: Sep | B27: =SUMIFS(Invoices!$L$9:$L$108,Invoices!$B$9:$B$108,">="&DATE($B$5,9,1),Invoices!$B$9:$B$108,"<"&DATE($B$5,10,1)) | C27: =SUMIFS(Invoices!$M$9:$M$108,Invoices!$B$9:$B$108,">="&DATE($B$5,9,1),Invoices!$B$9:$B$108,"<"&DATE($B$5,10,1)) | D27: =SUMIFS(Invoices!$O$9:$O$108,Invoices!$B$9:$B$108,">="&DATE($B$5,9,1),Invoices!$B$9:$B$108,"<"&DATE($B$5,10,1)) | E27: =IFERROR(D27/B27,0) | N27: Signal | O27: Count | P27: Status
A28: Oct | B28: =SUMIFS(Invoices!$L$9:$L$108,Invoices!$B$9:$B$108,">="&DATE($B$5,10,1),Invoices!$B$9:$B$108,"<"&DATE($B$5,11,1)) | C28: =SUMIFS(Invoices!$M$9:$M$108,Invoices!$B$9:$B$108,">="&DATE($B$5,10,1),Invoices!$B$9:$B$108,"<"&DATE($B$5,11,1)) | D28: =SUMIFS(Invoices!$O$9:$O$108,Invoices!$B$9:$B$108,">="&DATE($B$5,10,1),Invoices!$B$9:$B$108,"<"&DATE($B$5,11,1)) | E28: =IFERROR(D28/B28,0) | N28: Invoice Review | O28: =COUNTIF(Invoices!$W$9:$W$108,"REVIEW") | P28: =IF(O28=0,"Clear","Review")
A29: Nov | B29: =SUMIFS(Invoices!$L$9:$L$108,Invoices!$B$9:$B$108,">="&DATE($B$5,11,1),Invoices!$B$9:$B$108,"<"&DATE($B$5,12,1)) | C29: =SUMIFS(Invoices!$M$9:$M$108,Invoices!$B$9:$B$108,">="&DATE($B$5,11,1),Invoices!$B$9:$B$108,"<"&DATE($B$5,12,1)) | D29: =SUMIFS(Invoices!$O$9:$O$108,Invoices!$B$9:$B$108,">="&DATE($B$5,11,1),Invoices!$B$9:$B$108,"<"&DATE($B$5,12,1)) | E29: =IFERROR(D29/B29,0) | N29: Depletion Review | O29: =COUNTIF(Depletion!$O$9:$O$208,"REVIEW") | P29: =IF(O29=0,"Clear","Review")
A30: Dec | B30: =SUMIFS(Invoices!$L$9:$L$108,Invoices!$B$9:$B$108,">="&DATE($B$5,12,1),Invoices!$B$9:$B$108,"<"&DATE($B$5+1,1,1)) | C30: =SUMIFS(Invoices!$M$9:$M$108,Invoices!$B$9:$B$108,">="&DATE($B$5,12,1),Invoices!$B$9:$B$108,"<"&DATE($B$5+1,1,1)) | D30: =SUMIFS(Invoices!$O$9:$O$108,Invoices!$B$9:$B$108,">="&DATE($B$5,12,1),Invoices!$B$9:$B$108,"<"&DATE($B$5+1,1,1)) | E30: =IFERROR(D30/B30,0) | N30: 31+ day AR | O30: =COUNTIFS(Invoices!$T$9:$T$108,">30",Invoices!$Q$9:$Q$108,">0") | P30: =IF(O30=0,"Clear","Review")
N31: Open invoices | O31: =COUNTIF(Invoices!$Q$9:$Q$108,">0") | P31: =IF(O31=0,"Clear","Review")

Sheet Invoices
C1: INVOICES
C2: Authoritative invoice and payment ledger. Cream cells are editable; neutral cells calculate automatically.
A5: SEARCH | G5: STATUS | H5: All | J5: REP | K5: All | M5: AGING | N5: All | P5: START DATE | S5: END DATE
A6: RECORDS | B6: =COUNTIF($A$9:$A$108,"<>") | D6: REVENUE | E6: =SUM($L$9:$L$108) | G6: OPEN AR | H6: =SUM($Q$9:$Q$108) | J6: NEEDS REVIEW | K6: =COUNTIF($W$9:$W$108,"REVIEW") | M6: Use the Lagom menu for New Invoice, Record Payment and Reset Filters
A7: INVOICE INPUT | J7: ACCOUNT CONTEXT | L7: FINANCIALS | Q7: AR / STATUS | W7: QA
A8: Invoice # | B8: Invoice Date | C8: Account | D8: Sales Rep | E8: Account Type | F8: Terms | G8: Amount Paid | H8: Payment Date | I8: Notes | J8: City | K8: Channel | L8: Invoice Revenue | M8: Cases | N8: Total COGS | O8: Gross Profit | P8: Gross Margin | Q8: Balance Due | R8: Due Date | S8: Payment Status | T8: Days Past Due | U8: Aging | V8: Commission Eligible Date | W8: QA Status | X8: Search Key
A9: 1088 | B9: 46064 | C9: Wayzata Smoke Shop & Vape | D9: Tito | E9: Reorder | F9: Due on receipt | G9: 291.96 | H9: 46064 | J9: =IF($A9="","",IFERROR(VLOOKUP($C9,Setup!$A$36:$D$50,2,FALSE),"")) | K9: =IF($A9="","",IFERROR(VLOOKUP($C9,Setup!$A$36:$D$50,3,FALSE),"")) | L9: =IF($A9="","",SUMIF(Depletion!$A$9:$A$208,$A9,Depletion!$E$9:$E$208)) | M9: =IF($A9="","",SUMIF(Depletion!$A$9:$A$208,$A9,Depletion!$C$9:$C$208)) | N9: =IF($A9="","",SUMIF(Depletion!$A$9:$A$208,$A9,Depletion!$I$9:$I$208)) | O9: =IF($A9="","",$L9-$N9) | P9: =IF($A9="","",IFERROR($O9/$L9,0)) | Q9: =IF($A9="","",MAX($L9-$G9,0)) | R9: =IF($A9="","",IFERROR($B9+VLOOKUP($F9,Setup!$A$82:$B$88,2,FALSE),"")) | S9: =IF($A9="","",IF($L9=0,"Draft",IF($Q9<=0,"Paid",IF($G9>0,"Partial","Unpaid")))) | T9: =IF($A9="","",IF($Q9<=0,0,IF($R9="","",MAX(TODAY()-$R9,0)))) | U9: =IF($A9="","",IF($S9="Paid","Closed",IF($R9="","Review",IF(TODAY()<=$R9,"Current",IF($T9<=30,"1-30",IF($T9<=60,"31-60",IF($T9<=90,"61-90","90+"))))))) | V9: =IF($A9="","",IF(AND($S9="Paid",$H9<>""),$H9,"")) | W9: =IF($A9="","",IF(OR(COUNTIF($A$9:$A$108,$A9)>1,$B9="",$C9="",$D9="",$E9="",$F9="",$J9="",$K9="",$L9<=0,$G9<0,$G9>$L9,AND($S9="Paid",$H9="")),"REVIEW","OK")) | X9: =IF($A9="","",LOWER($A9&" "&$C9&" "&$D9&" "&$S9&" "&$J9&" "&$K9&" "&$I9))
A10: 1089 | B10: 46064 | C10: Long Lake Orono Smoke Shop | D10: Tito | E10: Reorder | F10: Due on receipt | G10: 291.96 | H10: 46064 | J10: =IF($A10="","",IFERROR(VLOOKUP($C10,Setup!$A$36:$D$50,2,FALSE),"")) | K10: =IF($A10="","",IFERROR(VLOOKUP($C10,Setup!$A$36:$D$50,3,FALSE),"")) | L10: =IF($A10="","",SUMIF(Depletion!$A$9:$A$208,$A10,Depletion!$E$9:$E$208)) | M10: =IF($A10="","",SUMIF(Depletion!$A$9:$A$208,$A10,Depletion!$C$9:$C$208)) | N10: =IF($A10="","",SUMIF(Depletion!$A$9:$A$208,$A10,Depletion!$I$9:$I$208)) | O10: =IF($A10="","",$L10-$N10) | P10: =IF($A10="","",IFERROR($O10/$L10,0)) | Q10: =IF($A10="","",MAX($L10-$G10,0)) | R10: =IF($A10="","",IFERROR($B10+VLOOKUP($F10,Setup!$A$82:$B$88,2,FALSE),"")) | S10: =IF($A10="","",IF($L10=0,"Draft",IF($Q10<=0,"Paid",IF($G10>0,"Partial","Unpaid")))) | T10: =IF($A10="","",IF($Q10<=0,0,IF($R10="","",MAX(TODAY()-$R10,0)))) | U10: =IF($A10="","",IF($S10="Paid","Closed",IF($R10="","Review",IF(TODAY()<=$R10,"Current",IF($T10<=30,"1-30",IF($T10<=60,"31-60",IF($T10<=90,"61-90","90+"))))))) | V10: =IF($A10="","",IF(AND($S10="Paid",$H10<>""),$H10,"")) | W10: =IF($A10="","",IF(OR(COUNTIF($A$9:$A$108,$A10)>1,$B10="",$C10="",$D10="",$E10="",$F10="",$J10="",$K10="",$L10<=0,$G10<0,$G10>$L10,AND($S10="Paid",$H10="")),"REVIEW","OK")) | X10: =IF($A10="","",LOWER($A10&" "&$C10&" "&$D10&" "&$S10&" "&$J10&" "&$K10&" "&$I10))
J11: =IF($A11="","",IFERROR(VLOOKUP($C11,Setup!$A$36:$D$50,2,FALSE),"")) | K11: =IF($A11="","",IFERROR(VLOOKUP($C11,Setup!$A$36:$D$50,3,FALSE),"")) | L11: =IF($A11="","",SUMIF(Depletion!$A$9:$A$208,$A11,Depletion!$E$9:$E$208)) | M11: =IF($A11="","",SUMIF(Depletion!$A$9:$A$208,$A11,Depletion!$C$9:$C$208)) | N11: =IF($A11="","",SUMIF(Depletion!$A$9:$A$208,$A11,Depletion!$I$9:$I$208)) | O11: =IF($A11="","",$L11-$N11) | P11: =IF($A11="","",IFERROR($O11/$L11,0)) | Q11: =IF($A11="","",MAX($L11-$G11,0)) | R11: =IF($A11="","",IFERROR($B11+VLOOKUP($F11,Setup!$A$82:$B$88,2,FALSE),"")) | S11: =IF($A11="","",IF($L11=0,"Draft",IF($Q11<=0,"Paid",IF($G11>0,"Partial","Unpaid")))) | T11: =IF($A11="","",IF($Q11<=0,0,IF($R11="","",MAX(TODAY()-$R11,0)))) | U11: =IF($A11="","",IF($S11="Paid","Closed",IF($R11="","Review",IF(TODAY()<=$R11,"Current",IF($T11<=30,"1-30",IF($T11<=60,"31-60",IF($T11<=90,"61-90","90+"))))))) | V11: =IF($A11="","",IF(AND($S11="Paid",$H11<>""),$H11,"")) | W11: =IF($A11="","",IF(OR(COUNTIF($A$9:$A$108,$A11)>1,$B11="",$C11="",$D11="",$E11="",$F11="",$J11="",$K11="",$L11<=0,$G11<0,$G11>$L11,AND($S11="Paid",$H11="")),"REVIEW","OK")) | X11: =IF($A11="","",LOWER($A11&" "&$C11&" "&$D11&" "&$S11&" "&$J11&" "&$K11&" "&$I11))
J12: =IF($A12="","",IFERROR(VLOOKUP($C12,Setup!$A$36:$D$50,2,FALSE),"")) | K12: =IF($A12="","",IFERROR(VLOOKUP($C12,Setup!$A$36:$D$50,3,FALSE),"")) | L12: =IF($A12="","",SUMIF(Depletion!$A$9:$A$208,$A12,Depletion!$E$9:$E$208)) | M12: =IF($A12="","",SUMIF(Depletion!$A$9:$A$208,$A12,Depletion!$C$9:$C$208)) | N12: =IF($A12="","",SUMIF(Depletion!$A$9:$A$208,$A12,Depletion!$I$9:$I$208)) | O12: =IF($A12="","",$L12-$N12) | P12: =IF($A12="","",IFERROR($O12/$L12,0)) | Q12: =IF($A12="","",MAX($L12-$G12,0)) | R12: =IF($A12="","",IFERROR($B12+VLOOKUP($F12,Setup!$A$82:$B$88,2,FALSE),"")) | S12: =IF($A12="","",IF($L12=0,"Draft",IF($Q12<=0,"Paid",IF($G12>0,"Partial","Unpaid")))) | T12: =IF($A12="","",IF($Q12<=0,0,IF($R12="","",MAX(TODAY()-$R12,0)))) | U12: =IF($A12="","",IF($S12="Paid","Closed",IF($R12="","Review",IF(TODAY()<=$R12,"Current",IF($T12<=30,"1-30",IF($T12<=60,"31-60",IF($T12<=90,"61-90","90+"))))))) | V12: =IF($A12="","",IF(AND($S12="Paid",$H12<>""),$H12,"")) | W12: =IF($A12="","",IF(OR(COUNTIF($A$9:$A$108,$A12)>1,$B12="",$C12="",$D12="",$E12="",$F12="",$J12="",$K12="",$L12<=0,$G12<0,$G12>$L12,AND($S12="Paid",$H12="")),"REVIEW","OK")) | X12: =IF($A12="","",LOWER($A12&" "&$C12&" "&$D12&" "&$S12&" "&$J12&" "&$K12&" "&$I12))
J13: =IF($A13="","",IFERROR(VLOOKUP($C13,Setup!$A$36:$D$50,2,FALSE),"")) | K13: =IF($A13="","",IFERROR(VLOOKUP($C13,Setup!$A$36:$D$50,3,FALSE),"")) | L13: =IF($A13="","",SUMIF(Depletion!$A$9:$A$208,$A13,Depletion!$E$9:$E$208)) | M13: =IF($A13="","",SUMIF(Depletion!$A$9:$A$208,$A13,Depletion!$C$9:$C$208)) | N13: =IF($A13="","",SUMIF(Depletion!$A$9:$A$208,$A13,Depletion!$I$9:$I$208)) | O13: =IF($A13="","",$L13-$N13) | P13: =IF($A13="","",IFERROR($O13/$L13,0)) | Q13: =IF($A13="","",MAX($L13-$G13,0)) | R13: =IF($A13="","",IFERROR($B13+VLOOKUP($F13,Setup!$A$82:$B$88,2,FALSE),"")) | S13: =IF($A13="","",IF($L13=0,"Draft",IF($Q13<=0,"Paid",IF($G13>0,"Partial","Unpaid")))) | T13: =IF($A13="","",IF($Q13<=0,0,IF($R13="","",MAX(TODAY()-$R13,0)))) | U13: =IF($A13="","",IF($S13="Paid","Closed",IF($R13="","Review",IF(TODAY()<=$R13,"Current",IF($T13<=30,"1-30",IF($T13<=60,"31-60",IF($T13<=90,"61-90","90+"))))))) | V13: =IF($A13="","",IF(AND($S13="Paid",$H13<>""),$H13,"")) | W13: =IF($A13="","",IF(OR(COUNTIF($A$9:$A$108,$A13)>1,$B13="",$C13="",$D13="",$E13="",$F13="",$J13="",$K13="",$L13<=0,$G13<0,$G13>$L13,AND($S13="Paid",$H13="")),"REVIEW","OK")) | X13: =IF($A13="","",LOWER($A13&" "&$C13&" "&$D13&" "&$S13&" "&$J13&" "&$K13&" "&$I13))
J14: =IF($A14="","",IFERROR(VLOOKUP($C14,Setup!$A$36:$D$50,2,FALSE),"")) | K14: =IF($A14="","",IFERROR(VLOOKUP($C14,Setup!$A$36:$D$50,3,FALSE),"")) | L14: =IF($A14="","",SUMIF(Depletion!$A$9:$A$208,$A14,Depletion!$E$9:$E$208)) | M14: =IF($A14="","",SUMIF(Depletion!$A$9:$A$208,$A14,Depletion!$C$9:$C$208)) | N14: =IF($A14="","",SUMIF(Depletion!$A$9:$A$208,$A14,Depletion!$I$9:$I$208)) | O14: =IF($A14="","",$L14-$N14) | P14: =IF($A14="","",IFERROR($O14/$L14,0)) | Q14: =IF($A14="","",MAX($L14-$G14,0)) | R14: =IF($A14="","",IFERROR($B14+VLOOKUP($F14,Setup!$A$82:$B$88,2,FALSE),"")) | S14: =IF($A14="","",IF($L14=0,"Draft",IF($Q14<=0,"Paid",IF($G14>0,"Partial","Unpaid")))) | T14: =IF($A14="","",IF($Q14<=0,0,IF($R14="","",MAX(TODAY()-$R14,0)))) | U14: =IF($A14="","",IF($S14="Paid","Closed",IF($R14="","Review",IF(TODAY()<=$R14,"Current",IF($T14<=30,"1-30",IF($T14<=60,"31-60",IF($T14<=90,"61-90","90+"))))))) | V14: =IF($A14="","",IF(AND($S14="Paid",$H14<>""),$H14,"")) | W14: =IF($A14="","",IF(OR(COUNTIF($A$9:$A$108,$A14)>1,$B14="",$C14="",$D14="",$E14="",$F14="",$J14="",$K14="",$L14<=0,$G14<0,$G14>$L14,AND($S14="Paid",$H14="")),"REVIEW","OK")) | X14: =IF($A14="","",LOWER($A14&" "&$C14&" "&$D14&" "&$S14&" "&$J14&" "&$K14&" "&$I14))
J15: =IF($A15="","",IFERROR(VLOOKUP($C15,Setup!$A$36:$D$50,2,FALSE),"")) | K15: =IF($A15="","",IFERROR(VLOOKUP($C15,Setup!$A$36:$D$50,3,FALSE),"")) | L15: =IF($A15="","",SUMIF(Depletion!$A$9:$A$208,$A15,Depletion!$E$9:$E$208)) | M15: =IF($A15="","",SUMIF(Depletion!$A$9:$A$208,$A15,Depletion!$C$9:$C$208)) | N15: =IF($A15="","",SUMIF(Depletion!$A$9:$A$208,$A15,Depletion!$I$9:$I$208)) | O15: =IF($A15="","",$L15-$N15) | P15: =IF($A15="","",IFERROR($O15/$L15,0)) | Q15: =IF($A15="","",MAX($L15-$G15,0)) | R15: =IF($A15="","",IFERROR($B15+VLOOKUP($F15,Setup!$A$82:$B$88,2,FALSE),"")) | S15: =IF($A15="","",IF($L15=0,"Draft",IF($Q15<=0,"Paid",IF($G15>0,"Partial","Unpaid")))) | T15: =IF($A15="","",IF($Q15<=0,0,IF($R15="","",MAX(TODAY()-$R15,0)))) | U15: =IF($A15="","",IF($S15="Paid","Closed",IF($R15="","Review",IF(TODAY()<=$R15,"Current",IF($T15<=30,"1-30",IF($T15<=60,"31-60",IF($T15<=90,"61-90","90+"))))))) | V15: =IF($A15="","",IF(AND($S15="Paid",$H15<>""),$H15,"")) | W15: =IF($A15="","",IF(OR(COUNTIF($A$9:$A$108,$A15)>1,$B15="",$C15="",$D15="",$E15="",$F15="",$J15="",$K15="",$L15<=0,$G15<0,$G15>$L15,AND($S15="Paid",$H15="")),"REVIEW","OK")) | X15: =IF($A15="","",LOWER($A15&" "&$C15&" "&$D15&" "&$S15&" "&$J15&" "&$K15&" "&$I15))
J16: =IF($A16="","",IFERROR(VLOOKUP($C16,Setup!$A$36:$D$50,2,FALSE),"")) | K16: =IF($A16="","",IFERROR(VLOOKUP($C16,Setup!$A$36:$D$50,3,FALSE),"")) | L16: =IF($A16="","",SUMIF(Depletion!$A$9:$A$208,$A16,Depletion!$E$9:$E$208)) | M16: =IF($A16="","",SUMIF(Depletion!$A$9:$A$208,$A16,Depletion!$C$9:$C$208)) | N16: =IF($A16="","",SUMIF(Depletion!$A$9:$A$208,$A16,Depletion!$I$9:$I$208)) | O16: =IF($A16="","",$L16-$N16) | P16: =IF($A16="","",IFERROR($O16/$L16,0)) | Q16: =IF($A16="","",MAX($L16-$G16,0)) | R16: =IF($A16="","",IFERROR($B16+VLOOKUP($F16,Setup!$A$82:$B$88,2,FALSE),"")) | S16: =IF($A16="","",IF($L16=0,"Draft",IF($Q16<=0,"Paid",IF($G16>0,"Partial","Unpaid")))) | T16: =IF($A16="","",IF($Q16<=0,0,IF($R16="","",MAX(TODAY()-$R16,0)))) | U16: =IF($A16="","",IF($S16="Paid","Closed",IF($R16="","Review",IF(TODAY()<=$R16,"Current",IF($T16<=30,"1-30",IF($T16<=60,"31-60",IF($T16<=90,"61-90","90+"))))))) | V16: =IF($A16="","",IF(AND($S16="Paid",$H16<>""),$H16,"")) | W16: =IF($A16="","",IF(OR(COUNTIF($A$9:$A$108,$A16)>1,$B16="",$C16="",$D16="",$E16="",$F16="",$J16="",$K16="",$L16<=0,$G16<0,$G16>$L16,AND($S16="Paid",$H16="")),"REVIEW","OK")) | X16: =IF($A16="","",LOWER($A16&" "&$C16&" "&$D16&" "&$S16&" "&$J16&" "&$K16&" "&$I16))
J17: =IF($A17="","",IFERROR(VLOOKUP($C17,Setup!$A$36:$D$50,2,FALSE),"")) | K17: =IF($A17="","",IFERROR(VLOOKUP($C17,Setup!$A$36:$D$50,3,FALSE),"")) | L17: =IF($A17="","",SUMIF(Depletion!$A$9:$A$208,$A17,Depletion!$E$9:$E$208)) | M17: =IF($A17="","",SUMIF(Depletion!$A$9:$A$208,$A17,Depletion!$C$9:$C$208)) | N17: =IF($A17="","",SUMIF(Depletion!$A$9:$A$208,$A17,Depletion!$I$9:$I$208)) | O17: =IF($A17="","",$L17-$N17) | P17: =IF($A17="","",IFERROR($O17/$L17,0)) | Q17: =IF($A17="","",MAX($L17-$G17,0)) | R17: =IF($A17="","",IFERROR($B17+VLOOKUP($F17,Setup!$A$82:$B$88,2,FALSE),"")) | S17: =IF($A17="","",IF($L17=0,"Draft",IF($Q17<=0,"Paid",IF($G17>0,"Partial","Unpaid")))) | T17: =IF($A17="","",IF($Q17<=0,0,IF($R17="","",MAX(TODAY()-$R17,0)))) | U17: =IF($A17="","",IF($S17="Paid","Closed",IF($R17="","Review",IF(TODAY()<=$R17,"Current",IF($T17<=30,"1-30",IF($T17<=60,"31-60",IF($T17<=90,"61-90","90+"))))))) | V17: =IF($A17="","",IF(AND($S17="Paid",$H17<>""),$H17,"")) | W17: =IF($A17="","",IF(OR(COUNTIF($A$9:$A$108,$A17)>1,$B17="",$C17="",$D17="",$E17="",$F17="",$J17="",$K17="",$L17<=0,$G17<0,$G17>$L17,AND($S17="Paid",$H17="")),"REVIEW","OK")) | X17: =IF($A17="","",LOWER($A17&" "&$C17&" "&$D17&" "&$S17&" "&$J17&" "&$K17&" "&$I17))
J18: =IF($A18="","",IFERROR(VLOOKUP($C18,Setup!$A$36:$D$50,2,FALSE),"")) | K18: =IF($A18="","",IFERROR(VLOOKUP($C18,Setup!$A$36:$D$50,3,FALSE),"")) | L18: =IF($A18="","",SUMIF(Depletion!$A$9:$A$208,$A18,Depletion!$E$9:$E$208)) | M18: =IF($A18="","",SUMIF(Depletion!$A$9:$A$208,$A18,Depletion!$C$9:$C$208)) | N18: =IF($A18="","",SUMIF(Depletion!$A$9:$A$208,$A18,Depletion!$I$9:$I$208)) | O18: =IF($A18="","",$L18-$N18) | P18: =IF($A18="","",IFERROR($O18/$L18,0)) | Q18: =IF($A18="","",MAX($L18-$G18,0)) | R18: =IF($A18="","",IFERROR($B18+VLOOKUP($F18,Setup!$A$82:$B$88,2,FALSE),"")) | S18: =IF($A18="","",IF($L18=0,"Draft",IF($Q18<=0,"Paid",IF($G18>0,"Partial","Unpaid")))) | T18: =IF($A18="","",IF($Q18<=0,0,IF($R18="","",MAX(TODAY()-$R18,0)))) | U18: =IF($A18="","",IF($S18="Paid","Closed",IF($R18="","Review",IF(TODAY()<=$R18,"Current",IF($T18<=30,"1-30",IF($T18<=60,"31-60",IF($T18<=90,"61-90","90+"))))))) | V18: =IF($A18="","",IF(AND($S18="Paid",$H18<>""),$H18,"")) | W18: =IF($A18="","",IF(OR(COUNTIF($A$9:$A$108,$A18)>1,$B18="",$C18="",$D18="",$E18="",$F18="",$J18="",$K18="",$L18<=0,$G18<0,$G18>$L18,AND($S18="Paid",$H18="")),"REVIEW","OK")) | X18: =IF($A18="","",LOWER($A18&" "&$C18&" "&$D18&" "&$S18&" "&$J18&" "&$K18&" "&$I18))
J19: =IF($A19="","",IFERROR(VLOOKUP($C19,Setup!$A$36:$D$50,2,FALSE),"")) | K19: =IF($A19="","",IFERROR(VLOOKUP($C19,Setup!$A$36:$D$50,3,FALSE),"")) | L19: =IF($A19="","",SUMIF(Depletion!$A$9:$A$208,$A19,Depletion!$E$9:$E$208)) | M19: =IF($A19="","",SUMIF(Depletion!$A$9:$A$208,$A19,Depletion!$C$9:$C$208)) | N19: =IF($A19="","",SUMIF(Depletion!$A$9:$A$208,$A19,Depletion!$I$9:$I$208)) | O19: =IF($A19="","",$L19-$N19) | P19: =IF($A19="","",IFERROR($O19/$L19,0)) | Q19: =IF($A19="","",MAX($L19-$G19,0)) | R19: =IF($A19="","",IFERROR($B19+VLOOKUP($F19,Setup!$A$82:$B$88,2,FALSE),"")) | S19: =IF($A19="","",IF($L19=0,"Draft",IF($Q19<=0,"Paid",IF($G19>0,"Partial","Unpaid")))) | T19: =IF($A19="","",IF($Q19<=0,0,IF($R19="","",MAX(TODAY()-$R19,0)))) | U19: =IF($A19="","",IF($S19="Paid","Closed",IF($R19="","Review",IF(TODAY()<=$R19,"Current",IF($T19<=30,"1-30",IF($T19<=60,"31-60",IF($T19<=90,"61-90","90+"))))))) | V19: =IF($A19="","",IF(AND($S19="Paid",$H19<>""),$H19,"")) | W19: =IF($A19="","",IF(OR(COUNTIF($A$9:$A$108,$A19)>1,$B19="",$C19="",$D19="",$E19="",$F19="",$J19="",$K19="",$L19<=0,$G19<0,$G19>$L19,AND($S19="Paid",$H19="")),"REVIEW","OK")) | X19: =IF($A19="","",LOWER($A19&" "&$C19&" "&$D19&" "&$S19&" "&$J19&" "&$K19&" "&$I19))
J20: =IF($A20="","",IFERROR(VLOOKUP($C20,Setup!$A$36:$D$50,2,FALSE),"")) | K20: =IF($A20="","",IFERROR(VLOOKUP($C20,Setup!$A$36:$D$50,3,FALSE),"")) | L20: =IF($A20="","",SUMIF(Depletion!$A$9:$A$208,$A20,Depletion!$E$9:$E$208)) | M20: =IF($A20="","",SUMIF(Depletion!$A$9:$A$208,$A20,Depletion!$C$9:$C$208)) | N20: =IF($A20="","",SUMIF(Depletion!$A$9:$A$208,$A20,Depletion!$I$9:$I$208)) | O20: =IF($A20="","",$L20-$N20) | P20: =IF($A20="","",IFERROR($O20/$L20,0)) | Q20: =IF($A20="","",MAX($L20-$G20,0)) | R20: =IF($A20="","",IFERROR($B20+VLOOKUP($F20,Setup!$A$82:$B$88,2,FALSE),"")) | S20: =IF($A20="","",IF($L20=0,"Draft",IF($Q20<=0,"Paid",IF($G20>0,"Partial","Unpaid")))) | T20: =IF($A20="","",IF($Q20<=0,0,IF($R20="","",MAX(TODAY()-$R20,0)))) | U20: =IF($A20="","",IF($S20="Paid","Closed",IF($R20="","Review",IF(TODAY()<=$R20,"Current",IF($T20<=30,"1-30",IF($T20<=60,"31-60",IF($T20<=90,"61-90","90+"))))))) | V20: =IF($A20="","",IF(AND($S20="Paid",$H20<>""),$H20,"")) | W20: =IF($A20="","",IF(OR(COUNTIF($A$9:$A$108,$A20)>1,$B20="",$C20="",$D20="",$E20="",$F20="",$J20="",$K20="",$L20<=0,$G20<0,$G20>$L20,AND($S20="Paid",$H20="")),"REVIEW","OK")) | X20: =IF($A20="","",LOWER($A20&" "&$C20&" "&$D20&" "&$S20&" "&$J20&" "&$K20&" "&$I20))
J21: =IF($A21="","",IFERROR(VLOOKUP($C21,Setup!$A$36:$D$50,2,FALSE),"")) | K21: =IF($A21="","",IFERROR(VLOOKUP($C21,Setup!$A$36:$D$50,3,FALSE),"")) | L21: =IF($A21="","",SUMIF(Depletion!$A$9:$A$208,$A21,Depletion!$E$9:$E$208)) | M21: =IF($A21="","",SUMIF(Depletion!$A$9:$A$208,$A21,Depletion!$C$9:$C$208)) | N21: =IF($A21="","",SUMIF(Depletion!$A$9:$A$208,$A21,Depletion!$I$9:$I$208)) | O21: =IF($A21="","",$L21-$N21) | P21: =IF($A21="","",IFERROR($O21/$L21,0)) | Q21: =IF($A21="","",MAX($L21-$G21,0)) | R21: =IF($A21="","",IFERROR($B21+VLOOKUP($F21,Setup!$A$82:$B$88,2,FALSE),"")) | S21: =IF($A21="","",IF($L21=0,"Draft",IF($Q21<=0,"Paid",IF($G21>0,"Partial","Unpaid")))) | T21: =IF($A21="","",IF($Q21<=0,0,IF($R21="","",MAX(TODAY()-$R21,0)))) | U21: =IF($A21="","",IF($S21="Paid","Closed",IF($R21="","Review",IF(TODAY()<=$R21,"Current",IF($T21<=30,"1-30",IF($T21<=60,"31-60",IF($T21<=90,"61-90","90+"))))))) | V21: =IF($A21="","",IF(AND($S21="Paid",$H21<>""),$H21,"")) | W21: =IF($A21="","",IF(OR(COUNTIF($A$9:$A$108,$A21)>1,$B21="",$C21="",$D21="",$E21="",$F21="",$J21="",$K21="",$L21<=0,$G21<0,$G21>$L21,AND($S21="Paid",$H21="")),"REVIEW","OK")) | X21: =IF($A21="","",LOWER($A21&" "&$C21&" "&$D21&" "&$S21&" "&$J21&" "&$K21&" "&$I21))
J22: =IF($A22="","",IFERROR(VLOOKUP($C22,Setup!$A$36:$D$50,2,FALSE),"")) | K22: =IF($A22="","",IFERROR(VLOOKUP($C22,Setup!$A$36:$D$50,3,FALSE),"")) | L22: =IF($A22="","",SUMIF(Depletion!$A$9:$A$208,$A22,Depletion!$E$9:$E$208)) | M22: =IF($A22="","",SUMIF(Depletion!$A$9:$A$208,$A22,Depletion!$C$9:$C$208)) | N22: =IF($A22="","",SUMIF(Depletion!$A$9:$A$208,$A22,Depletion!$I$9:$I$208)) | O22: =IF($A22="","",$L22-$N22) | P22: =IF($A22="","",IFERROR($O22/$L22,0)) | Q22: =IF($A22="","",MAX($L22-$G22,0)) | R22: =IF($A22="","",IFERROR($B22+VLOOKUP($F22,Setup!$A$82:$B$88,2,FALSE),"")) | S22: =IF($A22="","",IF($L22=0,"Draft",IF($Q22<=0,"Paid",IF($G22>0,"Partial","Unpaid")))) | T22: =IF($A22="","",IF($Q22<=0,0,IF($R22="","",MAX(TODAY()-$R22,0)))) | U22: =IF($A22="","",IF($S22="Paid","Closed",IF($R22="","Review",IF(TODAY()<=$R22,"Current",IF($T22<=30,"1-30",IF($T22<=60,"31-60",IF($T22<=90,"61-90","90+"))))))) | V22: =IF($A22="","",IF(AND($S22="Paid",$H22<>""),$H22,"")) | W22: =IF($A22="","",IF(OR(COUNTIF($A$9:$A$108,$A22)>1,$B22="",$C22="",$D22="",$E22="",$F22="",$J22="",$K22="",$L22<=0,$G22<0,$G22>$L22,AND($S22="Paid",$H22="")),"REVIEW","OK")) | X22: =IF($A22="","",LOWER($A22&" "&$C22&" "&$D22&" "&$S22&" "&$J22&" "&$K22&" "&$I22))
... J108: =IF($A108="","",IFERROR(VLOOKUP($C108,Setup!$A$36:$D$50,2,FALSE),"")) | K108: =IF($A108="","",IFERROR(VLOOKUP($C108,Setup!$A$36:$D$50,3,FALSE),"")) | L108: =IF($A108="","",SUMIF(Depletion!$A$9:$A$208,$A108,Depletion!$E$9:$E$208)) | M108: =IF($A108="","",SUMIF(Depletion!$A$9:$A$208,$A108,Depletion!$C$9:$C$208)) | N108: =IF($A108="","",SUMIF(Depletion!$A$9:$A$208,$A108,Depletion!$I$9:$I$208)) | O108: =IF($A108="","",$L108-$N108) | P108: =IF($A108="","",IFERROR($O108/$L108,0)) | Q108: =IF($A108="","",MAX($L108-$G108,0)) | R108: =IF($A108="","",IFERROR($B108+VLOOKUP($F108,Setup!$A$82:$B$88,2,FALSE),"")) | S108: =IF($A108="","",IF($L108=0,"Draft",IF($Q108<=0,"Paid",IF($G108>0,"Partial","Unpaid")))) | T108: =IF($A108="","",IF($Q108<=0,0,IF($R108="","",MAX(TODAY()-$R108,0)))) | U108: =IF($A108="","",IF($S108="Paid","Closed",IF($R108="","Review",IF(TODAY()<=$R108,"Current",IF($T108<=30,"1-30",IF($T108<=60,"31-60",IF($T108<=90,"61-90","90+"))))))) | V108: =IF($A108="","",IF(AND($S108="Paid",$H108<>""),$H108,"")) | W108: =IF($A108="","",IF(OR(COUNTIF($A$9:$A$108,$A108)>1,$B108="",$C108="",$D108="",$E108="",$F108="",$J108="",$K108="",$L108<=0,$G108<0,$G108>$L108,AND($S108="Paid",$H108="")),"REVIEW","OK")) | X108: =IF($A108="","",LOWER($A108&" "&$C108&" "&$D108&" "&$S108&" "&$J108&" "&$K108&" "&$I108))

Sheet Depletion
C1: DEPLETION
C2: Authoritative product-level sales ledger. Enter Invoice #, Product, Cases and Sale Price only.
A5: SEARCH | F5: REP | G5: All | I5: PRODUCT LINE | J5: All | L5: PRODUCT | M5: All | O5: QA | P5: All
A6: RECORDS | B6: =COUNTIF($A$9:$A$208,"<>") | D6: REVENUE | E6: =SUM($E$9:$E$208) | G6: CASES | H6: =SUM($C$9:$C$208) | J6: NEEDS REVIEW | K6: =COUNTIF($O$9:$O$208,"REVIEW") | L6: Use Lagom → Import Depletion or enter rows directly
A7: DEPLETION INPUT | E7: PRODUCT ECONOMICS | K7: INVOICE CONTEXT | O7: QA
A8: Invoice # | B8: Product | C8: Cases | D8: Sale Price | E8: Revenue | F8: SKU | G8: Product Line | H8: COGS / Case | I8: Total COGS | J8: Gross Profit | K8: Invoice Date | L8: Account | M8: Sales Rep | N8: Account Type | O8: QA Status | P8: Search Key
A9: 1088 | B9: Lagom - 24K Lemonade | C9: 1 | D9: 72.99 | E9: =IF(OR($A9="",$B9="",$C9="",$D9=""),"",$C9*$D9) | F9: =IF($B9="","",IFERROR(VLOOKUP($B9,Setup!$A$9:$H$30,2,FALSE),"")) | G9: =IF($B9="","",IFERROR(VLOOKUP($B9,Setup!$A$9:$H$30,5,FALSE),"")) | H9: =IF($B9="","",IFERROR(VLOOKUP($B9,Setup!$A$9:$H$30,6,FALSE),"")) | I9: =IF(OR($C9="",$H9=""),"",$C9*$H9) | J9: =IF(OR($E9="",$I9=""),"",$E9-$I9) | K9: =IF($A9="","",IFERROR(VLOOKUP($A9,Invoices!$A$9:$X$108,2,FALSE),"")) | L9: =IF($A9="","",IFERROR(VLOOKUP($A9,Invoices!$A$9:$X$108,3,FALSE),"")) | M9: =IF($A9="","",IFERROR(VLOOKUP($A9,Invoices!$A$9:$X$108,4,FALSE),"")) | N9: =IF($A9="","",IFERROR(VLOOKUP($A9,Invoices!$A$9:$X$108,5,FALSE),"")) | O9: =IF(AND($A9="",$B9="",$C9="",$D9=""),"",IF(OR($A9="",$B9="",$C9<=0,$D9<=0,$F9="",$H9="",$K9=""),"REVIEW","OK")) | P9: =IF($A9="","",LOWER($A9&" "&$B9&" "&$F9&" "&$G9&" "&$L9&" "&$M9&" "&$N9))
A10: 1088 | B10: Lagom - Strawberry Lime Fusion | C10: 1 | D10: 72.99 | E10: =IF(OR($A10="",$B10="",$C10="",$D10=""),"",$C10*$D10) | F10: =IF($B10="","",IFERROR(VLOOKUP($B10,Setup!$A$9:$H$30,2,FALSE),"")) | G10: =IF($B10="","",IFERROR(VLOOKUP($B10,Setup!$A$9:$H$30,5,FALSE),"")) | H10: =IF($B10="","",IFERROR(VLOOKUP($B10,Setup!$A$9:$H$30,6,FALSE),"")) | I10: =IF(OR($C10="",$H10=""),"",$C10*$H10) | J10: =IF(OR($E10="",$I10=""),"",$E10-$I10) | K10: =IF($A10="","",IFERROR(VLOOKUP($A10,Invoices!$A$9:$X$108,2,FALSE),"")) | L10: =IF($A10="","",IFERROR(VLOOKUP($A10,Invoices!$A$9:$X$108,3,FALSE),"")) | M10: =IF($A10="","",IFERROR(VLOOKUP($A10,Invoices!$A$9:$X$108,4,FALSE),"")) | N10: =IF($A10="","",IFERROR(VLOOKUP($A10,Invoices!$A$9:$X$108,5,FALSE),"")) | O10: =IF(AND($A10="",$B10="",$C10="",$D10=""),"",IF(OR($A10="",$B10="",$C10<=0,$D10<=0,$F10="",$H10="",$K10=""),"REVIEW","OK")) | P10: =IF($A10="","",LOWER($A10&" "&$B10&" "&$F10&" "&$G10&" "&$L10&" "&$M10&" "&$N10))
A11: 1088 | B11: Lagom - Blackberry Breeze | C11: 1 | D11: 72.99 | E11: =IF(OR($A11="",$B11="",$C11="",$D11=""),"",$C11*$D11) | F11: =IF($B11="","",IFERROR(VLOOKUP($B11,Setup!$A$9:$H$30,2,FALSE),"")) | G11: =IF($B11="","",IFERROR(VLOOKUP($B11,Setup!$A$9:$H$30,5,FALSE),"")) | H11: =IF($B11="","",IFERROR(VLOOKUP($B11,Setup!$A$9:$H$30,6,FALSE),"")) | I11: =IF(OR($C11="",$H11=""),"",$C11*$H11) | J11: =IF(OR($E11="",$I11=""),"",$E11-$I11) | K11: =IF($A11="","",IFERROR(VLOOKUP($A11,Invoices!$A$9:$X$108,2,FALSE),"")) | L11: =IF($A11="","",IFERROR(VLOOKUP($A11,Invoices!$A$9:$X$108,3,FALSE),"")) | M11: =IF($A11="","",IFERROR(VLOOKUP($A11,Invoices!$A$9:$X$108,4,FALSE),"")) | N11: =IF($A11="","",IFERROR(VLOOKUP($A11,Invoices!$A$9:$X$108,5,FALSE),"")) | O11: =IF(AND($A11="",$B11="",$C11="",$D11=""),"",IF(OR($A11="",$B11="",$C11<=0,$D11<=0,$F11="",$H11="",$K11=""),"REVIEW","OK")) | P11: =IF($A11="","",LOWER($A11&" "&$B11&" "&$F11&" "&$G11&" "&$L11&" "&$M11&" "&$N11))
A12: 1088 | B12: Lagom - Watermelon Refresher | C12: 1 | D12: 72.99 | E12: =IF(OR($A12="",$B12="",$C12="",$D12=""),"",$C12*$D12) | F12: =IF($B12="","",IFERROR(VLOOKUP($B12,Setup!$A$9:$H$30,2,FALSE),"")) | G12: =IF($B12="","",IFERROR(VLOOKUP($B12,Setup!$A$9:$H$30,5,FALSE),"")) | H12: =IF($B12="","",IFERROR(VLOOKUP($B12,Setup!$A$9:$H$30,6,FALSE),"")) | I12: =IF(OR($C12="",$H12=""),"",$C12*$H12) | J12: =IF(OR($E12="",$I12=""),"",$E12-$I12) | K12: =IF($A12="","",IFERROR(VLOOKUP($A12,Invoices!$A$9:$X$108,2,FALSE),"")) | L12: =IF($A12="","",IFERROR(VLOOKUP($A12,Invoices!$A$9:$X$108,3,FALSE),"")) | M12: =IF($A12="","",IFERROR(VLOOKUP($A12,Invoices!$A$9:$X$108,4,FALSE),"")) | N12: =IF($A12="","",IFERROR(VLOOKUP($A12,Invoices!$A$9:$X$108,5,FALSE),"")) | O12: =IF(AND($A12="",$B12="",$C12="",$D12=""),"",IF(OR($A12="",$B12="",$C12<=0,$D12<=0,$F12="",$H12="",$K12=""),"REVIEW","OK")) | P12: =IF($A12="","",LOWER($A12&" "&$B12&" "&$F12&" "&$G12&" "&$L12&" "&$M12&" "&$N12))
A13: 1089 | B13: Lagom - 24K Lemonade | C13: 1 | D13: 72.99 | E13: =IF(OR($A13="",$B13="",$C13="",$D13=""),"",$C13*$D13) | F13: =IF($B13="","",IFERROR(VLOOKUP($B13,Setup!$A$9:$H$30,2,FALSE),"")) | G13: =IF($B13="","",IFERROR(VLOOKUP($B13,Setup!$A$9:$H$30,5,FALSE),"")) | H13: =IF($B13="","",IFERROR(VLOOKUP($B13,Setup!$A$9:$H$30,6,FALSE),"")) | I13: =IF(OR($C13="",$H13=""),"",$C13*$H13) | J13: =IF(OR($E13="",$I13=""),"",$E13-$I13) | K13: =IF($A13="","",IFERROR(VLOOKUP($A13,Invoices!$A$9:$X$108,2,FALSE),"")) | L13: =IF($A13="","",IFERROR(VLOOKUP($A13,Invoices!$A$9:$X$108,3,FALSE),"")) | M13: =IF($A13="","",IFERROR(VLOOKUP($A13,Invoices!$A$9:$X$108,4,FALSE),"")) | N13: =IF($A13="","",IFERROR(VLOOKUP($A13,Invoices!$A$9:$X$108,5,FALSE),"")) | O13: =IF(AND($A13="",$B13="",$C13="",$D13=""),"",IF(OR($A13="",$B13="",$C13<=0,$D13<=0,$F13="",$H13="",$K13=""),"REVIEW","OK")) | P13: =IF($A13="","",LOWER($A13&" "&$B13&" "&$F13&" "&$G13&" "&$L13&" "&$M13&" "&$N13))
A14: 1089 | B14: Lagom - Strawberry Lime Fusion | C14: 1 | D14: 72.99 | E14: =IF(OR($A14="",$B14="",$C14="",$D14=""),"",$C14*$D14) | F14: =IF($B14="","",IFERROR(VLOOKUP($B14,Setup!$A$9:$H$30,2,FALSE),"")) | G14: =IF($B14="","",IFERROR(VLOOKUP($B14,Setup!$A$9:$H$30,5,FALSE),"")) | H14: =IF($B14="","",IFERROR(VLOOKUP($B14,Setup!$A$9:$H$30,6,FALSE),"")) | I14: =IF(OR($C14="",$H14=""),"",$C14*$H14) | J14: =IF(OR($E14="",$I14=""),"",$E14-$I14) | K14: =IF($A14="","",IFERROR(VLOOKUP($A14,Invoices!$A$9:$X$108,2,FALSE),"")) | L14: =IF($A14="","",IFERROR(VLOOKUP($A14,Invoices!$A$9:$X$108,3,FALSE),"")) | M14: =IF($A14="","",IFERROR(VLOOKUP($A14,Invoices!$A$9:$X$108,4,FALSE),"")) | N14: =IF($A14="","",IFERROR(VLOOKUP($A14,Invoices!$A$9:$X$108,5,FALSE),"")) | O14: =IF(AND($A14="",$B14="",$C14="",$D14=""),"",IF(OR($A14="",$B14="",$C14<=0,$D14<=0,$F14="",$H14="",$K14=""),"REVIEW","OK")) | P14: =IF($A14="","",LOWER($A14&" "&$B14&" "&$F14&" "&$G14&" "&$L14&" "&$M14&" "&$N14))
A15: 1089 | B15: Lagom - Blackberry Breeze | C15: 1 | D15: 72.99 | E15: =IF(OR($A15="",$B15="",$C15="",$D15=""),"",$C15*$D15) | F15: =IF($B15="","",IFERROR(VLOOKUP($B15,Setup!$A$9:$H$30,2,FALSE),"")) | G15: =IF($B15="","",IFERROR(VLOOKUP($B15,Setup!$A$9:$H$30,5,FALSE),"")) | H15: =IF($B15="","",IFERROR(VLOOKUP($B15,Setup!$A$9:$H$30,6,FALSE),"")) | I15: =IF(OR($C15="",$H15=""),"",$C15*$H15) | J15: =IF(OR($E15="",$I15=""),"",$E15-$I15) | K15: =IF($A15="","",IFERROR(VLOOKUP($A15,Invoices!$A$9:$X$108,2,FALSE),"")) | L15: =IF($A15="","",IFERROR(VLOOKUP($A15,Invoices!$A$9:$X$108,3,FALSE),"")) | M15: =IF($A15="","",IFERROR(VLOOKUP($A15,Invoices!$A$9:$X$108,4,FALSE),"")) | N15: =IF($A15="","",IFERROR(VLOOKUP($A15,Invoices!$A$9:$X$108,5,FALSE),"")) | O15: =IF(AND($A15="",$B15="",$C15="",$D15=""),"",IF(OR($A15="",$B15="",$C15<=0,$D15<=0,$F15="",$H15="",$K15=""),"REVIEW","OK")) | P15: =IF($A15="","",LOWER($A15&" "&$B15&" "&$F15&" "&$G15&" "&$L15&" "&$M15&" "&$N15))
A16: 1089 | B16: Lagom - Watermelon Refresher | C16: 1 | D16: 72.99 | E16: =IF(OR($A16="",$B16="",$C16="",$D16=""),"",$C16*$D16) | F16: =IF($B16="","",IFERROR(VLOOKUP($B16,Setup!$A$9:$H$30,2,FALSE),"")) | G16: =IF($B16="","",IFERROR(VLOOKUP($B16,Setup!$A$9:$H$30,5,FALSE),"")) | H16: =IF($B16="","",IFERROR(VLOOKUP($B16,Setup!$A$9:$H$30,6,FALSE),"")) | I16: =IF(OR($C16="",$H16=""),"",$C16*$H16) | J16: =IF(OR($E16="",$I16=""),"",$E16-$I16) | K16: =IF($A16="","",IFERROR(VLOOKUP($A16,Invoices!$A$9:$X$108,2,FALSE),"")) | L16: =IF($A16="","",IFERROR(VLOOKUP($A16,Invoices!$A$9:$X$108,3,FALSE),"")) | M16: =IF($A16="","",IFERROR(VLOOKUP($A16,Invoices!$A$9:$X$108,4,FALSE),"")) | N16: =IF($A16="","",IFERROR(VLOOKUP($A16,Invoices!$A$9:$X$108,5,FALSE),"")) | O16: =IF(AND($A16="",$B16="",$C16="",$D16=""),"",IF(OR($A16="",$B16="",$C16<=0,$D16<=0,$F16="",$H16="",$K16=""),"REVIEW","OK")) | P16: =IF($A16="","",LOWER($A16&" "&$B16&" "&$F16&" "&$G16&" "&$L16&" "&$M16&" "&$N16))
E17: =IF(OR($A17="",$B17="",$C17="",$D17=""),"",$C17*$D17) | F17: =IF($B17="","",IFERROR(VLOOKUP($B17,Setup!$A$9:$H$30,2,FALSE),"")) | G17: =IF($B17="","",IFERROR(VLOOKUP($B17,Setup!$A$9:$H$30,5,FALSE),"")) | H17: =IF($B17="","",IFERROR(VLOOKUP($B17,Setup!$A$9:$H$30,6,FALSE),"")) | I17: =IF(OR($C17="",$H17=""),"",$C17*$H17) | J17: =IF(OR($E17="",$I17=""),"",$E17-$I17) | K17: =IF($A17="","",IFERROR(VLOOKUP($A17,Invoices!$A$9:$X$108,2,FALSE),"")) | L17: =IF($A17="","",IFERROR(VLOOKUP($A17,Invoices!$A$9:$X$108,3,FALSE),"")) | M17: =IF($A17="","",IFERROR(VLOOKUP($A17,Invoices!$A$9:$X$108,4,FALSE),"")) | N17: =IF($A17="","",IFERROR(VLOOKUP($A17,Invoices!$A$9:$X$108,5,FALSE),"")) | O17: =IF(AND($A17="",$B17="",$C17="",$D17=""),"",IF(OR($A17="",$B17="",$C17<=0,$D17<=0,$F17="",$H17="",$K17=""),"REVIEW","OK")) | P17: =IF($A17="","",LOWER($A17&" "&$B17&" "&$F17&" "&$G17&" "&$L17&" "&$M17&" "&$N17))
E18: =IF(OR($A18="",$B18="",$C18="",$D18=""),"",$C18*$D18) | F18: =IF($B18="","",IFERROR(VLOOKUP($B18,Setup!$A$9:$H$30,2,FALSE),"")) | G18: =IF($B18="","",IFERROR(VLOOKUP($B18,Setup!$A$9:$H$30,5,FALSE),"")) | H18: =IF($B18="","",IFERROR(VLOOKUP($B18,Setup!$A$9:$H$30,6,FALSE),"")) | I18: =IF(OR($C18="",$H18=""),"",$C18*$H18) | J18: =IF(OR($E18="",$I18=""),"",$E18-$I18) | K18: =IF($A18="","",IFERROR(VLOOKUP($A18,Invoices!$A$9:$X$108,2,FALSE),"")) | L18: =IF($A18="","",IFERROR(VLOOKUP($A18,Invoices!$A$9:$X$108,3,FALSE),"")) | M18: =IF($A18="","",IFERROR(VLOOKUP($A18,Invoices!$A$9:$X$108,4,FALSE),"")) | N18: =IF($A18="","",IFERROR(VLOOKUP($A18,Invoices!$A$9:$X$108,5,FALSE),"")) | O18: =IF(AND($A18="",$B18="",$C18="",$D18=""),"",IF(OR($A18="",$B18="",$C18<=0,$D18<=0,$F18="",$H18="",$K18=""),"REVIEW","OK")) | P18: =IF($A18="","",LOWER($A18&" "&$B18&" "&$F18&" "&$G18&" "&$L18&" "&$M18&" "&$N18))
E19: =IF(OR($A19="",$B19="",$C19="",$D19=""),"",$C19*$D19) | F19: =IF($B19="","",IFERROR(VLOOKUP($B19,Setup!$A$9:$H$30,2,FALSE),"")) | G19: =IF($B19="","",IFERROR(VLOOKUP($B19,Setup!$A$9:$H$30,5,FALSE),"")) | H19: =IF($B19="","",IFERROR(VLOOKUP($B19,Setup!$A$9:$H$30,6,FALSE),"")) | I19: =IF(OR($C19="",$H19=""),"",$C19*$H19) | J19: =IF(OR($E19="",$I19=""),"",$E19-$I19) | K19: =IF($A19="","",IFERROR(VLOOKUP($A19,Invoices!$A$9:$X$108,2,FALSE),"")) | L19: =IF($A19="","",IFERROR(VLOOKUP($A19,Invoices!$A$9:$X$108,3,FALSE),"")) | M19: =IF($A19="","",IFERROR(VLOOKUP($A19,Invoices!$A$9:$X$108,4,FALSE),"")) | N19: =IF($A19="","",IFERROR(VLOOKUP($A19,Invoices!$A$9:$X$108,5,FALSE),"")) | O19: =IF(AND($A19="",$B19="",$C19="",$D19=""),"",IF(OR($A19="",$B19="",$C19<=0,$D19<=0,$F19="",$H19="",$K19=""),"REVIEW","OK")) | P19: =IF($A19="","",LOWER($A19&" "&$B19&" "&$F19&" "&$G19&" "&$L19&" "&$M19&" "&$N19))
E20: =IF(OR($A20="",$B20="",$C20="",$D20=""),"",$C20*$D20) | F20: =IF($B20="","",IFERROR(VLOOKUP($B20,Setup!$A$9:$H$30,2,FALSE),"")) | G20: =IF($B20="","",IFERROR(VLOOKUP($B20,Setup!$A$9:$H$30,5,FALSE),"")) | H20: =IF($B20="","",IFERROR(VLOOKUP($B20,Setup!$A$9:$H$30,6,FALSE),"")) | I20: =IF(OR($C20="",$H20=""),"",$C20*$H20) | J20: =IF(OR($E20="",$I20=""),"",$E20-$I20) | K20: =IF($A20="","",IFERROR(VLOOKUP($A20,Invoices!$A$9:$X$108,2,FALSE),"")) | L20: =IF($A20="","",IFERROR(VLOOKUP($A20,Invoices!$A$9:$X$108,3,FALSE),"")) | M20: =IF($A20="","",IFERROR(VLOOKUP($A20,Invoices!$A$9:$X$108,4,FALSE),"")) | N20: =IF($A20="","",IFERROR(VLOOKUP($A20,Invoices!$A$9:$X$108,5,FALSE),"")) | O20: =IF(AND($A20="",$B20="",$C20="",$D20=""),"",IF(OR($A20="",$B20="",$C20<=0,$D20<=0,$F20="",$H20="",$K20=""),"REVIEW","OK")) | P20: =IF($A20="","",LOWER($A20&" "&$B20&" "&$F20&" "&$G20&" "&$L20&" "&$M20&" "&$N20))
E21: =IF(OR($A21="",$B21="",$C21="",$D21=""),"",$C21*$D21) | F21: =IF($B21="","",IFERROR(VLOOKUP($B21,Setup!$A$9:$H$30,2,FALSE),"")) | G21: =IF($B21="","",IFERROR(VLOOKUP($B21,Setup!$A$9:$H$30,5,FALSE),"")) | H21: =IF($B21="","",IFERROR(VLOOKUP($B21,Setup!$A$9:$H$30,6,FALSE),"")) | I21: =IF(OR($C21="",$H21=""),"",$C21*$H21) | J21: =IF(OR($E21="",$I21=""),"",$E21-$I21) | K21: =IF($A21="","",IFERROR(VLOOKUP($A21,Invoices!$A$9:$X$108,2,FALSE),"")) | L21: =IF($A21="","",IFERROR(VLOOKUP($A21,Invoices!$A$9:$X$108,3,FALSE),"")) | M21: =IF($A21="","",IFERROR(VLOOKUP($A21,Invoices!$A$9:$X$108,4,FALSE),"")) | N21: =IF($A21="","",IFERROR(VLOOKUP($A21,Invoices!$A$9:$X$108,5,FALSE),"")) | O21: =IF(AND($A21="",$B21="",$C21="",$D21=""),"",IF(OR($A21="",$B21="",$C21<=0,$D21<=0,$F21="",$H21="",$K21=""),"REVIEW","OK")) | P21: =IF($A21="","",LOWER($A21&" "&$B21&" "&$F21&" "&$G21&" "&$L21&" "&$M21&" "&$N21))
E22: =IF(OR($A22="",$B22="",$C22="",$D22=""),"",$C22*$D22) | F22: =IF($B22="","",IFERROR(VLOOKUP($B22,Setup!$A$9:$H$30,2,FALSE),"")) | G22: =IF($B22="","",IFERROR(VLOOKUP($B22,Setup!$A$9:$H$30,5,FALSE),"")) | H22: =IF($B22="","",IFERROR(VLOOKUP($B22,Setup!$A$9:$H$30,6,FALSE),"")) | I22: =IF(OR($C22="",$H22=""),"",$C22*$H22) | J22: =IF(OR($E22="",$I22=""),"",$E22-$I22) | K22: =IF($A22="","",IFERROR(VLOOKUP($A22,Invoices!$A$9:$X$108,2,FALSE),"")) | L22: =IF($A22="","",IFERROR(VLOOKUP($A22,Invoices!$A$9:$X$108,3,FALSE),"")) | M22: =IF($A22="","",IFERROR(VLOOKUP($A22,Invoices!$A$9:$X$108,4,FALSE),"")) | N22: =IF($A22="","",IFERROR(VLOOKUP($A22,Invoices!$A$9:$X$108,5,FALSE),"")) | O22: =IF(AND($A22="",$B22="",$C22="",$D22=""),"",IF(OR($A22="",$B22="",$C22<=0,$D22<=0,$F22="",$H22="",$K22=""),"REVIEW","OK")) | P22: =IF($A22="","",LOWER($A22&" "&$B22&" "&$F22&" "&$G22&" "&$L22&" "&$M22&" "&$N22))
E23: =IF(OR($A23="",$B23="",$C23="",$D23=""),"",$C23*$D23) | F23: =IF($B23="","",IFERROR(VLOOKUP($B23,Setup!$A$9:$H$30,2,FALSE),"")) | G23: =IF($B23="","",IFERROR(VLOOKUP($B23,Setup!$A$9:$H$30,5,FALSE),"")) | H23: =IF($B23="","",IFERROR(VLOOKUP($B23,Setup!$A$9:$H$30,6,FALSE),"")) | I23: =IF(OR($C23="",$H23=""),"",$C23*$H23) | J23: =IF(OR($E23="",$I23=""),"",$E23-$I23) | K23: =IF($A23="","",IFERROR(VLOOKUP($A23,Invoices!$A$9:$X$108,2,FALSE),"")) | L23: =IF($A23="","",IFERROR(VLOOKUP($A23,Invoices!$A$9:$X$108,3,FALSE),"")) | M23: =IF($A23="","",IFERROR(VLOOKUP($A23,Invoices!$A$9:$X$108,4,FALSE),"")) | N23: =IF($A23="","",IFERROR(VLOOKUP($A23,Invoices!$A$9:$X$108,5,FALSE),"")) | O23: =IF(AND($A23="",$B23="",$C23="",$D23=""),"",IF(OR($A23="",$B23="",$C23<=0,$D23<=0,$F23="",$H23="",$K23=""),"REVIEW","OK")) | P23: =IF($A23="","",LOWER($A23&" "&$B23&" "&$F23&" "&$G23&" "&$L23&" "&$M23&" "&$N23))
E24: =IF(OR($A24="",$B24="",$C24="",$D24=""),"",$C24*$D24) | F24: =IF($B24="","",IFERROR(VLOOKUP($B24,Setup!$A$9:$H$30,2,FALSE),"")) | G24: =IF($B24="","",IFERROR(VLOOKUP($B24,Setup!$A$9:$H$30,5,FALSE),"")) | H24: =IF($B24="","",IFERROR(VLOOKUP($B24,Setup!$A$9:$H$30,6,FALSE),"")) | I24: =IF(OR($C24="",$H24=""),"",$C24*$H24) | J24: =IF(OR($E24="",$I24=""),"",$E24-$I24) | K24: =IF($A24="","",IFERROR(VLOOKUP($A24,Invoices!$A$9:$X$108,2,FALSE),"")) | L24: =IF($A24="","",IFERROR(VLOOKUP($A24,Invoices!$A$9:$X$108,3,FALSE),"")) | M24: =IF($A24="","",IFERROR(VLOOKUP($A24,Invoices!$A$9:$X$108,4,FALSE),"")) | N24: =IF($A24="","",IFERROR(VLOOKUP($A24,Invoices!$A$9:$X$108,5,FALSE),"")) | O24: =IF(AND($A24="",$B24="",$C24="",$D24=""),"",IF(OR($A24="",$B24="",$C24<=0,$D24<=0,$F24="",$H24="",$K24=""),"REVIEW","OK")) | P24: =IF($A24="","",LOWER($A24&" "&$B24&" "&$F24&" "&$G24&" "&$L24&" "&$M24&" "&$N24))
E25: =IF(OR($A25="",$B25="",$C25="",$D25=""),"",$C25*$D25) | F25: =IF($B25="","",IFERROR(VLOOKUP($B25,Setup!$A$9:$H$30,2,FALSE),"")) | G25: =IF($B25="","",IFERROR(VLOOKUP($B25,Setup!$A$9:$H$30,5,FALSE),"")) | H25: =IF($B25="","",IFERROR(VLOOKUP($B25,Setup!$A$9:$H$30,6,FALSE),"")) | I25: =IF(OR($C25="",$H25=""),"",$C25*$H25) | J25: =IF(OR($E25="",$I25=""),"",$E25-$I25) | K25: =IF($A25="","",IFERROR(VLOOKUP($A25,Invoices!$A$9:$X$108,2,FALSE),"")) | L25: =IF($A25="","",IFERROR(VLOOKUP($A25,Invoices!$A$9:$X$108,3,FALSE),"")) | M25: =IF($A25="","",IFERROR(VLOOKUP($A25,Invoices!$A$9:$X$108,4,FALSE),"")) | N25: =IF($A25="","",IFERROR(VLOOKUP($A25,Invoices!$A$9:$X$108,5,FALSE),"")) | O25: =IF(AND($A25="",$B25="",$C25="",$D25=""),"",IF(OR($A25="",$B25="",$C25<=0,$D25<=0,$F25="",$H25="",$K25=""),"REVIEW","OK")) | P25: =IF($A25="","",LOWER($A25&" "&$B25&" "&$F25&" "&$G25&" "&$L25&" "&$M25&" "&$N25))
E26: =IF(OR($A26="",$B26="",$C26="",$D26=""),"",$C26*$D26) | F26: =IF($B26="","",IFERROR(VLOOKUP($B26,Setup!$A$9:$H$30,2,FALSE),"")) | G26: =IF($B26="","",IFERROR(VLOOKUP($B26,Setup!$A$9:$H$30,5,FALSE),"")) | H26: =IF($B26="","",IFERROR(VLOOKUP($B26,Setup!$A$9:$H$30,6,FALSE),"")) | I26: =IF(OR($C26="",$H26=""),"",$C26*$H26) | J26: =IF(OR($E26="",$I26=""),"",$E26-$I26) | K26: =IF($A26="","",IFERROR(VLOOKUP($A26,Invoices!$A$9:$X$108,2,FALSE),"")) | L26: =IF($A26="","",IFERROR(VLOOKUP($A26,Invoices!$A$9:$X$108,3,FALSE),"")) | M26: =IF($A26="","",IFERROR(VLOOKUP($A26,Invoices!$A$9:$X$108,4,FALSE),"")) | N26: =IF($A26="","",IFERROR(VLOOKUP($A26,Invoices!$A$9:$X$108,5,FALSE),"")) | O26: =IF(AND($A26="",$B26="",$C26="",$D26=""),"",IF(OR($A26="",$B26="",$C26<=0,$D26<=0,$F26="",$H26="",$K26=""),"REVIEW","OK")) | P26: =IF($A26="","",LOWER($A26&" "&$B26&" "&$F26&" "&$G26&" "&$L26&" "&$M26&" "&$N26))
E27: =IF(OR($A27="",$B27="",$C27="",$D27=""),"",$C27*$D27) | F27: =IF($B27="","",IFERROR(VLOOKUP($B27,Setup!$A$9:$H$30,2,FALSE),"")) | G27: =IF($B27="","",IFERROR(VLOOKUP($B27,Setup!$A$9:$H$30,5,FALSE),"")) | H27: =IF($B27="","",IFERROR(VLOOKUP($B27,Setup!$A$9:$H$30,6,FALSE),"")) | I27: =IF(OR($C27="",$H27=""),"",$C27*$H27) | J27: =IF(OR($E27="",$I27=""),"",$E27-$I27) | K27: =IF($A27="","",IFERROR(VLOOKUP($A27,Invoices!$A$9:$X$108,2,FALSE),"")) | L27: =IF($A27="","",IFERROR(VLOOKUP($A27,Invoices!$A$9:$X$108,3,FALSE),"")) | M27: =IF($A27="","",IFERROR(VLOOKUP($A27,Invoices!$A$9:$X$108,4,FALSE),"")) | N27: =IF($A27="","",IFERROR(VLOOKUP($A27,Invoices!$A$9:$X$108,5,FALSE),"")) | O27: =IF(AND($A27="",$B27="",$C27="",$D27=""),"",IF(OR($A27="",$B27="",$C27<=0,$D27<=0,$F27="",$H27="",$K27=""),"REVIEW","OK")) | P27: =IF($A27="","",LOWER($A27&" "&$B27&" "&$F27&" "&$G27&" "&$L27&" "&$M27&" "&$N27))
E28: =IF(OR($A28="",$B28="",$C28="",$D28=""),"",$C28*$D28) | F28: =IF($B28="","",IFERROR(VLOOKUP($B28,Setup!$A$9:$H$30,2,FALSE),"")) | G28: =IF($B28="","",IFERROR(VLOOKUP($B28,Setup!$A$9:$H$30,5,FALSE),"")) | H28: =IF($B28="","",IFERROR(VLOOKUP($B28,Setup!$A$9:$H$30,6,FALSE),"")) | I28: =IF(OR($C28="",$H28=""),"",$C28*$H28) | J28: =IF(OR($E28="",$I28=""),"",$E28-$I28) | K28: =IF($A28="","",IFERROR(VLOOKUP($A28,Invoices!$A$9:$X$108,2,FALSE),"")) | L28: =IF($A28="","",IFERROR(VLOOKUP($A28,Invoices!$A$9:$X$108,3,FALSE),"")) | M28: =IF($A28="","",IFERROR(VLOOKUP($A28,Invoices!$A$9:$X$108,4,FALSE),"")) | N28: =IF($A28="","",IFERROR(VLOOKUP($A28,Invoices!$A$9:$X$108,5,FALSE),"")) | O28: =IF(AND($A28="",$B28="",$C28="",$D28=""),"",IF(OR($A28="",$B28="",$C28<=0,$D28<=0,$F28="",$H28="",$K28=""),"REVIEW","OK")) | P28: =IF($A28="","",LOWER($A28&" "&$B28&" "&$F28&" "&$G28&" "&$L28&" "&$M28&" "&$N28))
... E208: =IF(OR($A208="",$B208="",$C208="",$D208=""),"",$C208*$D208) | F208: =IF($B208="","",IFERROR(VLOOKUP($B208,Setup!$A$9:$H$30,2,FALSE),"")) | G208: =IF($B208="","",IFERROR(VLOOKUP($B208,Setup!$A$9:$H$30,5,FALSE),"")) | H208: =IF($B208="","",IFERROR(VLOOKUP($B208,Setup!$A$9:$H$30,6,FALSE),"")) | I208: =IF(OR($C208="",$H208=""),"",$C208*$H208) | J208: =IF(OR($E208="",$I208=""),"",$E208-$I208) | K208: =IF($A208="","",IFERROR(VLOOKUP($A208,Invoices!$A$9:$X$108,2,FALSE),"")) | L208: =IF($A208="","",IFERROR(VLOOKUP($A208,Invoices!$A$9:$X$108,3,FALSE),"")) | M208: =IF($A208="","",IFERROR(VLOOKUP($A208,Invoices!$A$9:$X$108,4,FALSE),"")) | N208: =IF($A208="","",IFERROR(VLOOKUP($A208,Invoices!$A$9:$X$108,5,FALSE),"")) | O208: =IF(AND($A208="",$B208="",$C208="",$D208=""),"",IF(OR($A208="",$B208="",$C208<=0,$D208<=0,$F208="",$H208="",$K208=""),"REVIEW","OK")) | P208: =IF($A208="","",LOWER($A208&" "&$B208&" "&$F208&" "&$G208&" "&$L208&" "&$M208&" "&$N208))

Sheet AR
C1: ACCOUNTS RECEIVABLE
C2: Live collections view derived from Invoices. Correct source records in Invoices, not here.
A5: SEARCH | F5: AGING | G5: All | I5: REP | J5: All
A6: OPEN AR | B6: =SUM(Invoices!$Q$9:$Q$108) | D6: OPEN INVOICES | E6: =COUNTIF(Invoices!$Q$9:$Q$108,">0") | G6: 90+ EXPOSURE | H6: =SUMIF(Invoices!$U$9:$U$108,"90+",Invoices!$Q$9:$Q$108) | J6: Open balances only; urgency rises with aging
A7: COLLECTIONS LEDGER
A8: Invoice # | B8: Account | C8: Sales Rep | D8: Invoice Date | E8: Due Date | F8: Invoice Total | G8: Amount Paid | H8: Balance Due | I8: Payment Status | J8: Days Past Due | K8: Aging | L8: Action | M8: Search Key
A9: =IF(Invoices!$Q9>0,Invoices!$A9,"") | B9: =IF($A9="","",Invoices!$C9) | C9: =IF($A9="","",Invoices!$D9) | D9: =IF($A9="","",Invoices!$B9) | E9: =IF($A9="","",Invoices!$R9) | F9: =IF($A9="","",Invoices!$L9) | G9: =IF($A9="","",Invoices!$G9) | H9: =IF($A9="","",Invoices!$Q9) | I9: =IF($A9="","",Invoices!$S9) | J9: =IF($A9="","",Invoices!$T9) | K9: =IF($A9="","",Invoices!$U9) | L9: =IF($A9="","",IF($K9="Current","Monitor",IF($K9="1-30","Follow Up",IF($K9="31-60","Escalate",IF($K9="61-90","Urgent",IF($K9="90+","Immediate Action","Monitor")))))) | M9: =IF($A9="","",LOWER($A9&" "&$B9&" "&$C9&" "&$K9&" "&$L9))
A10: =IF(Invoices!$Q10>0,Invoices!$A10,"") | B10: =IF($A10="","",Invoices!$C10) | C10: =IF($A10="","",Invoices!$D10) | D10: =IF($A10="","",Invoices!$B10) | E10: =IF($A10="","",Invoices!$R10) | F10: =IF($A10="","",Invoices!$L10) | G10: =IF($A10="","",Invoices!$G10) | H10: =IF($A10="","",Invoices!$Q10) | I10: =IF($A10="","",Invoices!$S10) | J10: =IF($A10="","",Invoices!$T10) | K10: =IF($A10="","",Invoices!$U10) | L10: =IF($A10="","",IF($K10="Current","Monitor",IF($K10="1-30","Follow Up",IF($K10="31-60","Escalate",IF($K10="61-90","Urgent",IF($K10="90+","Immediate Action","Monitor")))))) | M10: =IF($A10="","",LOWER($A10&" "&$B10&" "&$C10&" "&$K10&" "&$L10))
A11: =IF(Invoices!$Q11>0,Invoices!$A11,"") | B11: =IF($A11="","",Invoices!$C11) | C11: =IF($A11="","",Invoices!$D11) | D11: =IF($A11="","",Invoices!$B11) | E11: =IF($A11="","",Invoices!$R11) | F11: =IF($A11="","",Invoices!$L11) | G11: =IF($A11="","",Invoices!$G11) | H11: =IF($A11="","",Invoices!$Q11) | I11: =IF($A11="","",Invoices!$S11) | J11: =IF($A11="","",Invoices!$T11) | K11: =IF($A11="","",Invoices!$U11) | L11: =IF($A11="","",IF($K11="Current","Monitor",IF($K11="1-30","Follow Up",IF($K11="31-60","Escalate",IF($K11="61-90","Urgent",IF($K11="90+","Immediate Action","Monitor")))))) | M11: =IF($A11="","",LOWER($A11&" "&$B11&" "&$C11&" "&$K11&" "&$L11))
A12: =IF(Invoices!$Q12>0,Invoices!$A12,"") | B12: =IF($A12="","",Invoices!$C12) | C12: =IF($A12="","",Invoices!$D12) | D12: =IF($A12="","",Invoices!$B12) | E12: =IF($A12="","",Invoices!$R12) | F12: =IF($A12="","",Invoices!$L12) | G12: =IF($A12="","",Invoices!$G12) | H12: =IF($A12="","",Invoices!$Q12) | I12: =IF($A12="","",Invoices!$S12) | J12: =IF($A12="","",Invoices!$T12) | K12: =IF($A12="","",Invoices!$U12) | L12: =IF($A12="","",IF($K12="Current","Monitor",IF($K12="1-30","Follow Up",IF($K12="31-60","Escalate",IF($K12="61-90","Urgent",IF($K12="90+","Immediate Action","Monitor")))))) | M12: =IF($A12="","",LOWER($A12&" "&$B12&" "&$C12&" "&$K12&" "&$L12))
A13: =IF(Invoices!$Q13>0,Invoices!$A13,"") | B13: =IF($A13="","",Invoices!$C13) | C13: =IF($A13="","",Invoices!$D13) | D13: =IF($A13="","",Invoices!$B13) | E13: =IF($A13="","",Invoices!$R13) | F13: =IF($A13="","",Invoices!$L13) | G13: =IF($A13="","",Invoices!$G13) | H13: =IF($A13="","",Invoices!$Q13) | I13: =IF($A13="","",Invoices!$S13) | J13: =IF($A13="","",Invoices!$T13) | K13: =IF($A13="","",Invoices!$U13) | L13: =IF($A13="","",IF($K13="Current","Monitor",IF($K13="1-30","Follow Up",IF($K13="31-60","Escalate",IF($K13="61-90","Urgent",IF($K13="90+","Immediate Action","Monitor")))))) | M13: =IF($A13="","",LOWER($A13&" "&$B13&" "&$C13&" "&$K13&" "&$L13))
A14: =IF(Invoices!$Q14>0,Invoices!$A14,"") | B14: =IF($A14="","",Invoices!$C14) | C14: =IF($A14="","",Invoices!$D14) | D14: =IF($A14="","",Invoices!$B14) | E14: =IF($A14="","",Invoices!$R14) | F14: =IF($A14="","",Invoices!$L14) | G14: =IF($A14="","",Invoices!$G14) | H14: =IF($A14="","",Invoices!$Q14) | I14: =IF($A14="","",Invoices!$S14) | J14: =IF($A14="","",Invoices!$T14) | K14: =IF($A14="","",Invoices!$U14) | L14: =IF($A14="","",IF($K14="Current","Monitor",IF($K14="1-30","Follow Up",IF($K14="31-60","Escalate",IF($K14="61-90","Urgent",IF($K14="90+","Immediate Action","Monitor")))))) | M14: =IF($A14="","",LOWER($A14&" "&$B14&" "&$C14&" "&$K14&" "&$L14))
A15: =IF(Invoices!$Q15>0,Invoices!$A15,"") | B15: =IF($A15="","",Invoices!$C15) | C15: =IF($A15="","",Invoices!$D15) | D15: =IF($A15="","",Invoices!$B15) | E15: =IF($A15="","",Invoices!$R15) | F15: =IF($A15="","",Invoices!$L15) | G15: =IF($A15="","",Invoices!$G15) | H15: =IF($A15="","",Invoices!$Q15) | I15: =IF($A15="","",Invoices!$S15) | J15: =IF($A15="","",Invoices!$T15) | K15: =IF($A15="","",Invoices!$U15) | L15: =IF($A15="","",IF($K15="Current","Monitor",IF($K15="1-30","Follow Up",IF($K15="31-60","Escalate",IF($K15="61-90","Urgent",IF($K15="90+","Immediate Action","Monitor")))))) | M15: =IF($A15="","",LOWER($A15&" "&$B15&" "&$C15&" "&$K15&" "&$L15))
A16: =IF(Invoices!$Q16>0,Invoices!$A16,"") | B16: =IF($A16="","",Invoices!$C16) | C16: =IF($A16="","",Invoices!$D16) | D16: =IF($A16="","",Invoices!$B16) | E16: =IF($A16="","",Invoices!$R16) | F16: =IF($A16="","",Invoices!$L16) | G16: =IF($A16="","",Invoices!$G16) | H16: =IF($A16="","",Invoices!$Q16) | I16: =IF($A16="","",Invoices!$S16) | J16: =IF($A16="","",Invoices!$T16) | K16: =IF($A16="","",Invoices!$U16) | L16: =IF($A16="","",IF($K16="Current","Monitor",IF($K16="1-30","Follow Up",IF($K16="31-60","Escalate",IF($K16="61-90","Urgent",IF($K16="90+","Immediate Action","Monitor")))))) | M16: =IF($A16="","",LOWER($A16&" "&$B16&" "&$C16&" "&$K16&" "&$L16))
A17: =IF(Invoices!$Q17>0,Invoices!$A17,"") | B17: =IF($A17="","",Invoices!$C17) | C17: =IF($A17="","",Invoices!$D17) | D17: =IF($A17="","",Invoices!$B17) | E17: =IF($A17="","",Invoices!$R17) | F17: =IF($A17="","",Invoices!$L17) | G17: =IF($A17="","",Invoices!$G17) | H17: =IF($A17="","",Invoices!$Q17) | I17: =IF($A17="","",Invoices!$S17) | J17: =IF($A17="","",Invoices!$T17) | K17: =IF($A17="","",Invoices!$U17) | L17: =IF($A17="","",IF($K17="Current","Monitor",IF($K17="1-30","Follow Up",IF($K17="31-60","Escalate",IF($K17="61-90","Urgent",IF($K17="90+","Immediate Action","Monitor")))))) | M17: =IF($A17="","",LOWER($A17&" "&$B17&" "&$C17&" "&$K17&" "&$L17))
A18: =IF(Invoices!$Q18>0,Invoices!$A18,"") | B18: =IF($A18="","",Invoices!$C18) | C18: =IF($A18="","",Invoices!$D18) | D18: =IF($A18="","",Invoices!$B18) | E18: =IF($A18="","",Invoices!$R18) | F18: =IF($A18="","",Invoices!$L18) | G18: =IF($A18="","",Invoices!$G18) | H18: =IF($A18="","",Invoices!$Q18) | I18: =IF($A18="","",Invoices!$S18) | J18: =IF($A18="","",Invoices!$T18) | K18: =IF($A18="","",Invoices!$U18) | L18: =IF($A18="","",IF($K18="Current","Monitor",IF($K18="1-30","Follow Up",IF($K18="31-60","Escalate",IF($K18="61-90","Urgent",IF($K18="90+","Immediate Action","Monitor")))))) | M18: =IF($A18="","",LOWER($A18&" "&$B18&" "&$C18&" "&$K18&" "&$L18))
A19: =IF(Invoices!$Q19>0,Invoices!$A19,"") | B19: =IF($A19="","",Invoices!$C19) | C19: =IF($A19="","",Invoices!$D19) | D19: =IF($A19="","",Invoices!$B19) | E19: =IF($A19="","",Invoices!$R19) | F19: =IF($A19="","",Invoices!$L19) | G19: =IF($A19="","",Invoices!$G19) | H19: =IF($A19="","",Invoices!$Q19) | I19: =IF($A19="","",Invoices!$S19) | J19: =IF($A19="","",Invoices!$T19) | K19: =IF($A19="","",Invoices!$U19) | L19: =IF($A19="","",IF($K19="Current","Monitor",IF($K19="1-30","Follow Up",IF($K19="31-60","Escalate",IF($K19="61-90","Urgent",IF($K19="90+","Immediate Action","Monitor")))))) | M19: =IF($A19="","",LOWER($A19&" "&$B19&" "&$C19&" "&$K19&" "&$L19))
A20: =IF(Invoices!$Q20>0,Invoices!$A20,"") | B20: =IF($A20="","",Invoices!$C20) | C20: =IF($A20="","",Invoices!$D20) | D20: =IF($A20="","",Invoices!$B20) | E20: =IF($A20="","",Invoices!$R20) | F20: =IF($A20="","",Invoices!$L20) | G20: =IF($A20="","",Invoices!$G20) | H20: =IF($A20="","",Invoices!$Q20) | I20: =IF($A20="","",Invoices!$S20) | J20: =IF($A20="","",Invoices!$T20) | K20: =IF($A20="","",Invoices!$U20) | L20: =IF($A20="","",IF($K20="Current","Monitor",IF($K20="1-30","Follow Up",IF($K20="31-60","Escalate",IF($K20="61-90","Urgent",IF($K20="90+","Immediate Action","Monitor")))))) | M20: =IF($A20="","",LOWER($A20&" "&$B20&" "&$C20&" "&$K20&" "&$L20))
... A108: =IF(Invoices!$Q108>0,Invoices!$A108,"") | B108: =IF($A108="","",Invoices!$C108) | C108: =IF($A108="","",Invoices!$D108) | D108: =IF($A108="","",Invoices!$B108) | E108: =IF($A108="","",Invoices!$R108) | F108: =IF($A108="","",Invoices!$L108) | G108: =IF($A108="","",Invoices!$G108) | H108: =IF($A108="","",Invoices!$Q108) | I108: =IF($A108="","",Invoices!$S108) | J108: =IF($A108="","",Invoices!$T108) | K108: =IF($A108="","",Invoices!$U108) | L108: =IF($A108="","",IF($K108="Current","Monitor",IF($K108="1-30","Follow Up",IF($K108="31-60","Escalate",IF($K108="61-90","Urgent",IF($K108="90+","Immediate Action","Monitor")))))) | M108: =IF($A108="","",LOWER($A108&" "&$B108&" "&$C108&" "&$K108&" "&$L108))

Sheet Reports
C1: REPORTS
C2: Consolidated product, account and sales-rep analysis from the canonical ledgers.
A5: START DATE | B5: 46023 | D5: END DATE | E5: 46387 | G5: SALES REP | H5: All | J5: ACCOUNT | K5: All | M5: PRODUCT LINE | N5: All
A7: Product Performance | H7: Account Performance
A9: Product | B9: Cases | C9: Revenue | D9: COGS | E9: Gross Profit | F9: Margin | H9: Account | I9: City | J9: Revenue | K9: Cases | L9: Invoice Count | M9: Current Open AR | N9: Last Order
A10: =Setup!A9 | B10: =IF($A10="","",SUMIFS(Depletion!$C$9:$C$208,Depletion!$B$9:$B$208,$A10,Depletion!$K$9:$K$208,">="&$B$5,Depletion!$K$9:$K$208,"<="&$E$5,Depletion!$M$9:$M$208,IF($H$5="All","*",$H$5),Depletion!$L$9:$L$208,IF($K$5="All","*",$K$5),Depletion!$G$9:$G$208,IF($N$5="All","*",$N$5))) | C10: =IF($A10="","",SUMIFS(Depletion!$E$9:$E$208,Depletion!$B$9:$B$208,$A10,Depletion!$K$9:$K$208,">="&$B$5,Depletion!$K$9:$K$208,"<="&$E$5,Depletion!$M$9:$M$208,IF($H$5="All","*",$H$5),Depletion!$L$9:$L$208,IF($K$5="All","*",$K$5),Depletion!$G$9:$G$208,IF($N$5="All","*",$N$5))) | D10: =IF($A10="","",SUMIFS(Depletion!$I$9:$I$208,Depletion!$B$9:$B$208,$A10,Depletion!$K$9:$K$208,">="&$B$5,Depletion!$K$9:$K$208,"<="&$E$5,Depletion!$M$9:$M$208,IF($H$5="All","*",$H$5),Depletion!$L$9:$L$208,IF($K$5="All","*",$K$5),Depletion!$G$9:$G$208,IF($N$5="All","*",$N$5))) | E10: =IF($A10="","",$C10-$D10) | F10: =IFERROR($E10/$C10,0) | H10: =Setup!A36 | I10: =IF($H10="","",IFERROR(VLOOKUP($H10,Setup!$A$36:$D$50,2,FALSE),"")) | J10: =IF($H10="","",SUMIFS(Invoices!$L$9:$L$108,Invoices!$C$9:$C$108,$H10,Invoices!$B$9:$B$108,">="&$B$5,Invoices!$B$9:$B$108,"<="&$E$5,Invoices!$D$9:$D$108,IF($H$5="All","*",$H$5))) | K10: =IF($H10="","",SUMIFS(Invoices!$M$9:$M$108,Invoices!$C$9:$C$108,$H10,Invoices!$B$9:$B$108,">="&$B$5,Invoices!$B$9:$B$108,"<="&$E$5,Invoices!$D$9:$D$108,IF($H$5="All","*",$H$5))) | L10: =IF($H10="","",COUNTIFS(Invoices!$C$9:$C$108,$H10,Invoices!$B$9:$B$108,">="&$B$5,Invoices!$B$9:$B$108,"<="&$E$5,Invoices!$D$9:$D$108,IF($H$5="All","*",$H$5))) | M10: =IF($H10="","",SUMIF(Invoices!$C$9:$C$108,$H10,Invoices!$Q$9:$Q$108)) | N10: =IF($H10="","",IFERROR(MAXIFS(Invoices!$B$9:$B$108,Invoices!$C$9:$C$108,$H10),""))
